Workbook

Sheet Provider
A1: First Name | B1: Last Name | C1: Gender | D1: Professional Suffix 1 | E1: Professional Suffix 2 | F1: Professional Suffix 3 | G1: Specialty 1 | H1: Specialty 2 | I1: Specialty 3 | J1: Specialty 4 | K1: Specialty 5 | L1: Patients Accepted | M1: Practice Name | N1: Location 1 | O1: Location 2 | P1: Location 3 | Q1: Location 4 | R1: Location 5 | S1: NPI Number | T1: Headshot Link | U1: Education 1 | V1: Education 2 | W1: Education 3 | X1: Education 4 | Y1: Education 5 | Z1: Professional Statement | AA1: Board Certification 1 | AB1: Sub Board Certification 1 | AC1: Board Certification 2 | AD1: Sub Board Certification 2 | AE1: Board Certification 3 | AF1: Sub Board Certification 3 | AG1: Board Certification 4 | AH1: Sub Board Certification 4 | AI1: Board Certification 5 | AJ1: Sub Board Certification 5 | AK1: Professional Memberships 1 | AL1: Professional Memberships 2 | AM1: Professional Memberships 3 | AN1: Professional Memberships 4 | AO1: Professional Memberships 5 | AP1: Awards and Publications 1 | AQ1: Awards and Publications 2 | AR1: Awards and Publications 3 | AS1: Awards and Publications 4 | AT1: Awards and Publications 5 | AU1: Hospital Affiliation 1 | AV1: Hospital Affiliation 2 | AW1: Hospital Affiliation 3 | AX1: Hospital Affiliation 4 | AY1: Hospital Affiliation 5 | AZ1: Additional Languages Spoken 1 | BA1: Additional Languages Spoken 2 | BB1: Additional Languages Spoken 3 | BC1: Practice Cloud ID | BD1: Provider Cloud ID | BE1: Provider Type | BF1: Salesforce Contact ID | BG1: Enterprise Scheduling Flag | BH1: Opt Out of Ratings | BI1: Provider Type (Substatus) ID | BJ1: Professional Suffix ID 1 | BK1: Professional Suffix ID 2 | BL1: Professional Suffix ID 3 | BM1: Specialty ID 1 | BN1: Specialty ID 2 | BO1: Specialty ID 3 | BP1: Specialty ID 4 | BQ1: Specialty ID 5 | BR1: Location ID 1 | BS1: Location ID 2 | BT1: Location ID 3 | BU1: Location ID 4 | BV1: Location ID 5 | BW1: Board Cert ID 1 | BX1: Sub Board Cert ID 1 | BY1: Board Cert ID 2 | BZ1: Sub Board Cert ID 2 | CA1: Board Cert ID 3 | CB1: Sub Board Cert ID 3 | CC1: Board Cert ID 4 | CD1: Sub Board Cert ID 4 | CE1: Board Cert ID 5 | CF1: Sub Board Cert ID 5 | CG1: Hospital Affiliation ID 1 | CH1: Hospital Affiliation ID 2 | CI1: Hospital Affiliation ID 3 | CJ1: Hospital Affiliation ID 4 | CK1: Hospital Affiliation ID 5 | CL1: Language ID 1 | CM1: Language ID 2 | CN1: Language ID 3 | CO1: Facility Address | CP1: Facility City | CQ1: Facility Zip | CR1: Facility State | CS1: Address line 2 | CT1: Matched
A2: Amanda | B2: Walker | C2: Female | G2: =IFERROR(VLOOKUP(BM2, ValidationAndReference!J:K, 2, FALSE), "") | L2: Both | M2: LifeStance Health | N2: =IFERROR(INDEX(Location!X:X, MATCH(BR2, Location!W:W, 0)), "") | O2: =IFERROR(INDEX(Location!X:X, MATCH(BS2, Location!W:W, 0)), "") | S2: 1003055393 | T2: https://prod-clinicians-photo.s3.amazonaws.com/1003055393.jpg | U2: PhD, Binghamton University | Z2: Amanda Walker, LCSW, provides compassionate and goaloriented therapy to individuals, couples, and families across Massachusetts. She works with adolescents, young adults, and adults, helping them navigate lifeâs challenges with a supportive and collaborative approach. Whether addressing anxiety, bipolar disorder, or relationship concerns, Amanda tailors treatment to meet each clientâs unique needs, fostering resilience and emotional wellbeing. Amanda has a deep passion for working with individuals facing major life transitions, including midlife changes, reproductive challenges, and postpartum depression and anxiety. She understands the emotional toll these experiences can take and strives to create a safe space where clients can process their emotions and develop coping strategies. With a strong commitment to supporting womenâs mental health, she empowers clients to regain confidence and balance in their lives. Specializing in both individual and couples therapy, Amanda integrates evidencebased techniques such as Cognitive Behavioral Therapy CBT, and Dialectical Behavior Therapy DBT to promote meaningful change. She is particularly skilled in working with first responders, LGBTQ individuals, and veterans, addressing the unique mental health concerns these communities may face. Her approach is rooted in empathy, understanding, and a dedication to helping clients achieve personal growth. Outside of her work, Amanda enjoys painting, cooking, and engaging in sports. She finds joy in creativity and movement, using these activities as a source of relaxation and personal fulfillment. Amanda is honored to serve individuals and families across Massachusetts, providing the guidance and support needed to navigate lifeâs complexities with strength and clarity. | AZ2: English | BC2: pt_B8LtUoRcYkWdny_20xbxdB | BE2: Practitioner - Full Profile | BG2: No | BI2: =IFERROR(INDEX(ValidationAndReference!P:P, MATCH(BE2, ValidationAndReference!Q:Q, 0)), "") | BJ2: =IFERROR(INDEX(ValidationAndReference!F:F, MATCH(D2, ValidationAndReference!G:G, 0)), "") | BK2: =IFERROR(INDEX(ValidationAndReference!F:F, MATCH(E2, ValidationAndReference!G:G, 0)), "") | BL2: =IFERROR(INDEX(ValidationAndReference!F:F, MATCH(F2, ValidationAndReference!G:G, 0)), "") | BR2: lo_mif8U7nWSU-EYq8liS2VYB | BS2: lo_N-mYRnhFs0OO_SnP_I3_wx | CL2: =IFERROR(INDEX(ValidationAndReference!V:V, MATCH(AZ2, ValidationAndReference!W:W, 0)), "") | CM2: =IFERROR(INDEX(ValidationAndReference!V:V, MATCH(BA2, ValidationAndReference!W:W, 0)), "") | CN2: =IFERROR(INDEX(ValidationAndReference!V:V, MATCH(BB2, ValidationAndReference!W:W, 0)), "") | CO2: 5 Hampshire St | CP2: Mansfield | CQ2: 2048 | CR2: MA | CT2: No - Facility Zip
A3: Amanda | B3: Walker | C3: Female | G3: =IFERROR(VLOOKUP(BM3, ValidationAndReference!J:K, 2, FALSE), "") | L3: Both | M3: LifeStance Health | N3: =IFERROR(INDEX(Location!X:X, MATCH(BR3, Location!W:W, 0)), "") | O3: =IFERROR(INDEX(Location!X:X, MATCH(BS3, Location!W:W, 0)), "") | S3: 1003055393 | T3: https://prod-clinicians-photo.s3.amazonaws.com/1003055393.jpg | U3: PhD, Binghamton University | Z3: Amanda Walker, LCSW, provides compassionate and goaloriented therapy to individuals, couples, and families across Massachusetts. She works with adolescents, young adults, and adults, helping them navigate lifeâs challenges with a supportive and collaborative approach. Whether addressing anxiety, bipolar disorder, or relationship concerns, Amanda tailors treatment to meet each clientâs unique needs, fostering resilience and emotional wellbeing. Amanda has a deep passion for working with individuals facing major life transitions, including midlife changes, reproductive challenges, and postpartum depression and anxiety. She understands the emotional toll these experiences can take and strives to create a safe space where clients can process their emotions and develop coping strategies. With a strong commitment to supporting womenâs mental health, she empowers clients to regain confidence and balance in their lives. Specializing in both individual and couples therapy, Amanda integrates evidencebased techniques such as Cognitive Behavioral Therapy CBT, and Dialectical Behavior Therapy DBT to promote meaningful change. She is particularly skilled in working with first responders, LGBTQ individuals, and veterans, addressing the unique mental health concerns these communities may face. Her approach is rooted in empathy, understanding, and a dedication to helping clients achieve personal growth. Outside of her work, Amanda enjoys painting, cooking, and engaging in sports. She finds joy in creativity and movement, using these activities as a source of relaxation and personal fulfillment. Amanda is honored to serve individuals and families across Massachusetts, providing the guidance and support needed to navigate lifeâs complexities with strength and clarity. | AZ3: English | BC3: pt_B8LtUoRcYkWdny_20xbxdB | BE3: Practitioner - Full Profile | BG3: No | BI3: =IFERROR(INDEX(ValidationAndReference!P:P, MATCH(BE3, ValidationAndReference!Q:Q, 0)), "") | BJ3: =IFERROR(INDEX(ValidationAndReference!F:F, MATCH(D3, ValidationAndReference!G:G, 0)), "") | BK3: =IFERROR(INDEX(ValidationAndReference!F:F, MATCH(E3, ValidationAndReference!G:G, 0)), "") | BL3: =IFERROR(INDEX(ValidationAndReference!F:F, MATCH(F3, ValidationAndReference!G:G, 0)), "") | BR3: lo_mif8U7nWSU-EYq8liS2VYB | BS3: lo_N-mYRnhFs0OO_SnP_I3_wx | CL3: =IFERROR(INDEX(ValidationAndReference!V:V, MATCH(AZ3, ValidationAndReference!W:W, 0)), "") | CM3: =IFERROR(INDEX(ValidationAndReference!V:V, MATCH(BA3, ValidationAndReference!W:W, 0)), "") | CN3: =IFERROR(INDEX(ValidationAndReference!V:V, MATCH(BB3, ValidationAndReference!W:W, 0)), "") | CO3: 5 Hampshire St | CP3: Mansfield | CQ3: 2048 | CR3: MA | CT3: No - Facility Zip
A4: Marci | B4: Langevin | C4: Female | D4: MSW | E4: LICSW | G4: =IFERROR(VLOOKUP(BM4, ValidationAndReference!J:K, 2, FALSE), "") | L4: Both | M4: LifeStance Health | N4: =IFERROR(INDEX(Location!X:X, MATCH(BR4, Location!W:W, 0)), "") | O4: =IFERROR(INDEX(Location!X:X, MATCH(BS4, Location!W:W, 0)), "") | S4: 1003065186 | T4: https://prod-clinicians-photo.s3.amazonaws.com/1003065186.jpg | U4: MSW, Bridgewater State College | Z4: Marci Langevin is an Independently Licensed Clinical Social Worker and Mental Health Provider who has a top notch ability to hear the voice of her clientsâ and truly understand their experience. Marci specializes in cognitive behavioral therapy and motivational counseling that helps propel clients to reach therapeutic goal achievement. Marciâs compassion and skill in helping individuals and families is of such value in a time when so many desire a safe therapeutic environment where they can receive caring help that really makes a difference in their life. From the moment you meet Marci it is clear that her style is to identify the mental health and wellness needs of her clients with care. She is genuinely interested in her clientsâ thoughts and feelings. Her therapeutic methodology is to help her clients to identify their presenting problem, understand their thoughts and behaviors, and guide them towards awareness and resolution. She holds a masterâs degree in Social Work. Prior to joining our team, Marci provided individual, couple, and family counseling in an outpatient mental health facility in MA. In addition, she holds a research based background in issues of discrimination and oppression, has created and facilitated several therapeutic treatment groups including drug and alcohol recovery, and the use of artistic and creative expression for those experiencing depression, anxiety andor trauma. | AZ4: English | BC4: pt_B8LtUoRcYkWdny_20xbxdB | BE4: Practitioner - Full Profile | BG4: No | BI4: =IFERROR(INDEX(ValidationAndReference!P:P, MATCH(BE4, ValidationAndReference!Q:Q, 0)), "") | BJ4: =IFERROR(INDEX(ValidationAndReference!F:F, MATCH(D4, ValidationAndReference!G:G, 0)), "") | BK4: =IFERROR(INDEX(ValidationAndReference!F:F, MATCH(E4, ValidationAndReference!G:G, 0)), "") | BL4: =IFERROR(INDEX(ValidationAndReference!F:F, MATCH(F4, ValidationAndReference!G:G, 0)), "") | BM4: 352 | BR4: lo_mif8U7nWSU-EYq8liS2VYB | BS4: lo_N-mYRnhFs0OO_SnP_I3_wx | CL4: =IFERROR(INDEX(ValidationAndReference!V:V, MATCH(AZ4, ValidationAndReference!W:W, 0)), "") | CM4: =IFERROR(INDEX(ValidationAndReference!V:V, MATCH(BA4, ValidationAndReference!W:W, 0)), "") | CN4: =IFERROR(INDEX(ValidationAndReference!V:V, MATCH(BB4, ValidationAndReference!W:W, 0)), "") | CO4: 5 Hampshire St | CP4: Mansfield | CQ4: 2048 | CR4: MA | CT4: No - Facility Zip
A5: Marci | B5: Langevin | C5: Female | D5: MSW | E5: LICSW | G5: =IFERROR(VLOOKUP(BM5, ValidationAndReference!J:K, 2, FALSE), "") | L5: Both | M5: LifeStance Health | N5: =IFERROR(INDEX(Location!X:X, MATCH(BR5, Location!W:W, 0)), "") | O5: =IFERROR(INDEX(Location!X:X, MATCH(BS5, Location!W:W, 0)), "") | S5: 1003065186 | T5: https://prod-clinicians-photo.s3.amazonaws.com/1003065186.jpg | U5: MSW, Bridgewater State College | Z5: Marci Langevin is an Independently Licensed Clinical Social Worker and Mental Health Provider who has a top notch ability to hear the voice of her clientsâ and truly understand their experience. Marci specializes in cognitive behavioral therapy and motivational counseling that helps propel clients to reach therapeutic goal achievement. Marciâs compassion and skill in helping individuals and families is of such value in a time when so many desire a safe therapeutic environment where they can receive caring help that really makes a difference in their life. From the moment you meet Marci it is clear that her style is to identify the mental health and wellness needs of her clients with care. She is genuinely interested in her clientsâ thoughts and feelings. Her therapeutic methodology is to help her clients to identify their presenting problem, understand their thoughts and behaviors, and guide them towards awareness and resolution. She holds a masterâs degree in Social Work. Prior to joining our team, Marci provided individual, couple, and family counseling in an outpatient mental health facility in MA. In addition, she holds a research based background in issues of discrimination and oppression, has created and facilitated several therapeutic treatment groups including drug and alcohol recovery, and the use of artistic and creative expression for those experiencing depression, anxiety andor trauma. | AZ5: English | BC5: pt_B8LtUoRcYkWdny_20xbxdB | BE5: Practitioner - Full Profile | BG5: No | BI5: =IFERROR(INDEX(ValidationAndReference!P:P, MATCH(BE5, ValidationAndReference!Q:Q, 0)), "") | BJ5: =IFERROR(INDEX(ValidationAndReference!F:F, MATCH(D5, ValidationAndReference!G:G, 0)), "") | BK5: =IFERROR(INDEX(ValidationAndReference!F:F, MATCH(E5, ValidationAndReference!G:G, 0)), "") | BL5: =IFERROR(INDEX(ValidationAndReference!F:F, MATCH(F5, ValidationAndReference!G:G, 0)), "") | BM5: 352 | BR5: lo_mif8U7nWSU-EYq8liS2VYB | BS5: lo_N-mYRnhFs0OO_SnP_I3_wx | CL5: =IFERROR(INDEX(ValidationAndReference!V:V, MATCH(AZ5, ValidationAndReference!W:W, 0)), "") | CM5: =IFERROR(INDEX(ValidationAndReference!V:V, MATCH(BA5, ValidationAndReference!W:W, 0)), "") | CN5: =IFERROR(INDEX(ValidationAndReference!V:V, MATCH(BB5, ValidationAndReference!W:W, 0)), "") | CO5: 5 Hampshire St | CP5: Mansfield | CQ5: 2048 | CR5: MA | CT5: No - Facility Zip
A6: Marci | B6: Langevin | C6: Female | D6: MSW | E6: LICSW | G6: =IFERROR(VLOOKUP(BM6, ValidationAndReference!J:K, 2, FALSE), "") | L6: Both | M6: LifeStance Health | N6: =IFERROR(INDEX(Location!X:X, MATCH(BR6, Location!W:W, 0)), "") | O6: =IFERROR(INDEX(Location!X:X, MATCH(BS6, Location!W:W, 0)), "") | S6: 1003065186 | T6: https://prod-clinicians-photo.s3.amazonaws.com/1003065186.jpg | U6: MSW, Bridgewater State College | Z6: Marci Langevin is an Independently Licensed Clinical Social Worker and Mental Health Provider who has a top notch ability to hear the voice of her clientsâ and truly understand their experience. Marci specializes in cognitive behavioral therapy and motivational counseling that helps propel clients to reach therapeutic goal achievement. Marciâs compassion and skill in helping individuals and families is of such value in a time when so many desire a safe therapeutic environment where they can receive caring help that really makes a difference in their life. From the moment you meet Marci it is clear that her style is to identify the mental health and wellness needs of her clients with care. She is genuinely interested in her clientsâ thoughts and feelings. Her therapeutic methodology is to help her clients to identify their presenting problem, understand their thoughts and behaviors, and guide them towards awareness and resolution. She holds a masterâs degree in Social Work. Prior to joining our team, Marci provided individual, couple, and family counseling in an outpatient mental health facility in MA. In addition, she holds a research based background in issues of discrimination and oppression, has created and facilitated several therapeutic treatment groups including drug and alcohol recovery, and the use of artistic and creative expression for those experiencing depression, anxiety andor trauma. | AZ6: English | BC6: pt_B8LtUoRcYkWdny_20xbxdB | BE6: Practitioner - Full Profile | BG6: No | BI6: =IFERROR(INDEX(ValidationAndReference!P:P, MATCH(BE6, ValidationAndReference!Q:Q, 0)), "") | BJ6: =IFERROR(INDEX(ValidationAndReference!F:F, MATCH(D6, ValidationAndReference!G:G, 0)), "") | BK6: =IFERROR(INDEX(ValidationAndReference!F:F, MATCH(E6, ValidationAndReference!G:G, 0)), "") | BL6: =IFERROR(INDEX(ValidationAndReference!F:F, MATCH(F6, ValidationAndReference!G:G, 0)), "") | BM6: 352 | BR6: lo_te0vo8TuekWyL5gMnjPK1w | BS6: lo_c9GJzBULJ0KYW9u1EWEsUB | CL6: =IFERROR(INDEX(ValidationAndReference!V:V, MATCH(AZ6, ValidationAndReference!W:W, 0)), "") | CM6: =IFERROR(INDEX(ValidationAndReference!V:V, MATCH(BA6, ValidationAndReference!W:W, 0)), "") | CN6: =IFERROR(INDEX(ValidationAndReference!V:V, MATCH(BB6, ValidationAndReference!W:W, 0)), "") | CO6: 45 Shawmut Rd | CP6: Canton | CQ6: 2021 | CR6: MA | CT6: No - Facility Zip
A7: Marci | B7: Langevin | C7: Female | D7: MSW | E7: LICSW | G7: =IFERROR(VLOOKUP(BM7, ValidationAndReference!J:K, 2, FALSE), "") | L7: Both | M7: LifeStance Health | N7: =IFERROR(INDEX(Location!X:X, MATCH(BR7, Location!W:W, 0)), "") | O7: =IFERROR(INDEX(Location!X:X, MATCH(BS7, Location!W:W, 0)), "") | S7: 1003065186 | T7: https://prod-clinicians-photo.s3.amazonaws.com/1003065186.jpg | U7: MSW, Bridgewater State College | Z7: Marci Langevin is an Independently Licensed Clinical Social Worker and Mental Health Provider who has a top notch ability to hear the voice of her clientsâ and truly understand their experience. Marci specializes in cognitive behavioral therapy and motivational counseling that helps propel clients to reach therapeutic goal achievement. Marciâs compassion and skill in helping individuals and families is of such value in a time when so many desire a safe therapeutic environment where they can receive caring help that really makes a difference in their life. From the moment you meet Marci it is clear that her style is to identify the mental health and wellness needs of her clients with care. She is genuinely interested in her clientsâ thoughts and feelings. Her therapeutic methodology is to help her clients to identify their presenting problem, understand their thoughts and behaviors, and guide them towards awareness and resolution. She holds a masterâs degree in Social Work. Prior to joining our team, Marci provided individual, couple, and family counseling in an outpatient mental health facility in MA. In addition, she holds a research based background in issues of discrimination and oppression, has created and facilitated several therapeutic treatment groups including drug and alcohol recovery, and the use of artistic and creative expression for those experiencing depression, anxiety andor trauma. | AZ7: English | BC7: pt_B8LtUoRcYkWdny_20xbxdB | BE7: Practitioner - Full Profile | BG7: No | BI7: =IFERROR(INDEX(ValidationAndReference!P:P, MATCH(BE7, ValidationAndReference!Q:Q, 0)), "") | BJ7: =IFERROR(INDEX(ValidationAndReference!F:F, MATCH(D7, ValidationAndReference!G:G, 0)), "") | BK7: =IFERROR(INDEX(ValidationAndReference!F:F, MATCH(E7, ValidationAndReference!G:G, 0)), "") | BL7: =IFERROR(INDEX(ValidationAndReference!F:F, MATCH(F7, ValidationAndReference!G:G, 0)), "") | BM7: 352 | BR7: lo_te0vo8TuekWyL5gMnjPK1w | BS7: lo_c9GJzBULJ0KYW9u1EWEsUB | CL7: =IFERROR(INDEX(ValidationAndReference!V:V, MATCH(AZ7, ValidationAndReference!W:W, 0)), "") | CM7: =IFERROR(INDEX(ValidationAndReference!V:V, MATCH(BA7, ValidationAndReference!W:W, 0)), "") | CN7: =IFERROR(INDEX(ValidationAndReference!V:V, MATCH(BB7, ValidationAndReference!W:W, 0)), "") | CO7: 45 Shawmut Rd | CP7: Canton | CQ7: 2021 | CR7: MA | CT7: No - Facility Zip
A8: Marci | B8: Langevin | C8: Female | D8: MSW | E8: LICSW | G8: =IFERROR(VLOOKUP(BM8, ValidationAndReference!J:K, 2, FALSE), "") | L8: Both | M8: LifeStance Health | N8: =IFERROR(INDEX(Location!X:X, MATCH(BR8, Location!W:W, 0)), "") | O8: =IFERROR(INDEX(Location!X:X, MATCH(BS8, Location!W:W, 0)), "") | S8: 1003065186 | T8: https://prod-clinicians-photo.s3.amazonaws.com/1003065186.jpg | U8: MSW, Bridgewater State College | Z8: Marci Langevin is an Independently Licensed Clinical Social Worker and Mental Health Provider who has a top notch ability to hear the voice of her clientsâ and truly understand their experience. Marci specializes in cognitive behavioral therapy and motivational counseling that helps propel clients to reach therapeutic goal achievement. Marciâs compassion and skill in helping individuals and families is of such value in a time when so many desire a safe therapeutic environment where they can receive caring help that really makes a difference in their life. From the moment you meet Marci it is clear that her style is to identify the mental health and wellness needs of her clients with care. She is genuinely interested in her clientsâ thoughts and feelings. Her therapeutic methodology is to help her clients to identify their presenting problem, understand their thoughts and behaviors, and guide them towards awareness and resolution. She holds a masterâs degree in Social Work. Prior to joining our team, Marci provided individual, couple, and family counseling in an outpatient mental health facility in MA. In addition, she holds a research based background in issues of discrimination and oppression, has created and facilitated several therapeutic treatment groups including drug and alcohol recovery, and the use of artistic and creative expression for those experiencing depression, anxiety andor trauma. | AZ8: English | BC8: pt_B8LtUoRcYkWdny_20xbxdB | BE8: Practitioner - Full Profile | BG8: No | BI8: =IFERROR(INDEX(ValidationAndReference!P:P, MATCH(BE8, ValidationAndReference!Q:Q, 0)), "") | BJ8: =IFERROR(INDEX(ValidationAndReference!F:F, MATCH(D8, ValidationAndReference!G:G, 0)), "") | BK8: =IFERROR(INDEX(ValidationAndReference!F:F, MATCH(E8, ValidationAndReference!G:G, 0)), "") | BL8: =IFERROR(INDEX(ValidationAndReference!F:F, MATCH(F8, ValidationAndReference!G:G, 0)), "") | BM8: 352 | BR8: lo_WGSx6xN8302ASv6YVggXbh | BS8: lo_8kwZD7BrWkmw6LTpfZ-4yB | CL8: =IFERROR(INDEX(ValidationAndReference!V:V, MATCH(AZ8, ValidationAndReference!W:W, 0)), "") | CM8: =IFERROR(INDEX(ValidationAndReference!V:V, MATCH(BA8, ValidationAndReference!W:W, 0)), "") | CN8: =IFERROR(INDEX(ValidationAndReference!V:V, MATCH(BB8, ValidationAndReference!W:W, 0)), "") | CO8: 175 Paramount Dr | CP8: Raynham | CQ8: 2767 | CR8: MA | CT8: No - Facility Zip
A9: Marci | B9: Langevin | C9: Female | D9: MSW | E9: LICSW | G9: =IFERROR(VLOOKUP(BM9, ValidationAndReference!J:K, 2, FALSE), "") | L9: Both | M9: LifeStance Health | N9: =IFERROR(INDEX(Location!X:X, MATCH(BR9, Location!W:W, 0)), "") | O9: =IFERROR(INDEX(Location!X:X, MATCH(BS9, Location!W:W, 0)), "") | S9: 1003065186 | T9: https://prod-clinicians-photo.s3.amazonaws.com/1003065186.jpg | U9: MSW, Bridgewater State College | Z9: Marci Langevin is an Independently Licensed Clinical Social Worker and Mental Health Provider who has a top notch ability to hear the voice of her clientsâ and truly understand their experience. Marci specializes in cognitive behavioral therapy and motivational counseling that helps propel clients to reach therapeutic goal achievement. Marciâs compassion and skill in helping individuals and families is of such value in a time when so many desire a safe therapeutic environment where they can receive caring help that really makes a difference in their life. From the moment you meet Marci it is clear that her style is to identify the mental health and wellness needs of her clients with care. She is genuinely interested in her clientsâ thoughts and feelings. Her therapeutic methodology is to help her clients to identify their presenting problem, understand their thoughts and behaviors, and guide them towards awareness and resolution. She holds a masterâs degree in Social Work. Prior to joining our team, Marci provided individual, couple, and family counseling in an outpatient mental health facility in MA. In addition, she holds a research based background in issues of discrimination and oppression, has created and facilitated several therapeutic treatment groups including drug and alcohol recovery, and the use of artistic and creative expression for those experiencing depression, anxiety andor trauma. | AZ9: English | BC9: pt_B8LtUoRcYkWdny_20xbxdB | BE9: Practitioner - Full Profile | BG9: No | BI9: =IFERROR(INDEX(ValidationAndReference!P:P, MATCH(BE9, ValidationAndReference!Q:Q, 0)), "") | BJ9: =IFERROR(INDEX(ValidationAndReference!F:F, MATCH(D9, ValidationAndReference!G:G, 0)), "") | BK9: =IFERROR(INDEX(ValidationAndReference!F:F, MATCH(E9, ValidationAndReference!G:G, 0)), "") | BL9: =IFERROR(INDEX(ValidationAndReference!F:F, MATCH(F9, ValidationAndReference!G:G, 0)), "") | BM9: 352 | BR9: lo_WGSx6xN8302ASv6YVggXbh | BS9: lo_8kwZD7BrWkmw6LTpfZ-4yB | CL9: =IFERROR(INDEX(ValidationAndReference!V:V, MATCH(AZ9, ValidationAndReference!W:W, 0)), "") | CM9: =IFERROR(INDEX(ValidationAndReference!V:V, MATCH(BA9, ValidationAndReference!W:W, 0)), "") | CN9: =IFERROR(INDEX(ValidationAndReference!V:V, MATCH(BB9, ValidationAndReference!W:W, 0)), "") | CO9: 175 Paramount Dr | CP9: Raynham | CQ9: 2767 | CR9: MA | CT9: No - Facility Zip
A10: Kara | B10: Naylon | C10: Female | D10: PsyD | E10: PhD | G10: =IFERROR(VLOOKUP(BM10, ValidationAndReference!J:K, 2, FALSE), "") | L10: Both | M10: LifeStance Health | N10: =IFERROR(INDEX(Location!X:X, MATCH(BR10, Location!W:W, 0)), "") | O10: =IFERROR(INDEX(Location!X:X, MATCH(BS10, Location!W:W, 0)), "") | S10: 1003446782 | T10: https://prod-clinicians-photo.s3.amazonaws.com/1003446782.jpg | U10: PsyD, Adler University | Z10: Dr. Naylon is a clinical neuropsychologist who provides comprehensive neuropsychological evaluations and treatment for adults with a wide range of neurological, neurodegenerative, medical, and psychological conditions and complications that impact cognitive functioning. Evaluations consist of an indepth clinical interview to obtain a thorough and unique understanding of each individual, their background, and their presenting concerns followed by comprehensive neuropsychological testing. Assessment results are interpreted in the context of each individualâs unique circumstances. Feedback on results and interpretation is provided to patients and includes detailed descriptions of strengths and weaknesses, diagnostic impressions and implications, and tailored recommendations to ameliorate presenting concerns and improve daily life experience. Dr. Naylonâs clinical interests include neurodegenerative and neurological conditions dementia, movement disorders, epilepsy, multiple sclerosis, etc., complex medical complicationsconditions and impact on cognition, the impact of sleep and psychological symptomsconditions on cognition, eating disorders, traumatic brain injury, and stroke. Dr. Naylon provides more indepth intervention and treatment to facilitate implementation of tailored recommendations yielded from neuropsychological evaluations. She provides cognitive rehabilitation therapy to help patients capitalize on cognitive strengths and ameliorate weaknesses. She also provides cognitive behavioral therapy for insomnia to improve sleep and, subsequently, cognitive and mood symptoms. Dr. Naylon received her bachelorâs degree in Biology and Psychology from John Carroll University. She received her doctoral degree in Clinical Psychology with specialization in Neuropsychology from Adler University. She completed a predoctoral internship in Clinical Neuropsychology at the VA North Texas Healthcare System and a twoyear fellowship in Clinical Neuropsychology at the University of Massachusetts Medical School. | AZ10: English | BC10: pt_B8LtUoRcYkWdny_20xbxdB | BE10: Practitioner - Full Profile | BG10: No | BI10: =IFERROR(INDEX(ValidationAndReference!P:P, MATCH(BE10, ValidationAndReference!Q:Q, 0)), "") | BJ10: =IFERROR(INDEX(ValidationAndReference!F:F, MATCH(D10, ValidationAndReference!G:G, 0)), "") | BK10: =IFERROR(INDEX(ValidationAndReference!F:F, MATCH(E10, ValidationAndReference!G:G, 0)), "") | BL10: =IFERROR(INDEX(ValidationAndReference!F:F, MATCH(F10, ValidationAndReference!G:G, 0)), "") | BM10: 337 | BR10: lo_WTxCl_PGJkydSgfSTKd1mx | BS10: lo_6Q6bTr0VKkuCN9evdqEA9B | CL10: =IFERROR(INDEX(ValidationAndReference!V:V, MATCH(AZ10, ValidationAndReference!W:W, 0)), "") | CM10: =IFERROR(INDEX(ValidationAndReference!V:V, MATCH(BA10, ValidationAndReference!W:W, 0)), "") | CN10: =IFERROR(INDEX(ValidationAndReference!V:V, MATCH(BB10, ValidationAndReference!W:W, 0)), "") | CO10: 169 Libbey Pkwy | CP10: Weymouth | CQ10: 2189 | CR10: MA | CT10: No - Facility Zip
A11: Kara | B11: Naylon | C11: Female | D11: PsyD | E11: PhD | G11: =IFERROR(VLOOKUP(BM11, ValidationAndReference!J:K, 2, FALSE), "") | L11: Both | M11: LifeStance Health | N11: =IFERROR(INDEX(Location!X:X, MATCH(BR11, Location!W:W, 0)), "") | O11: =IFERROR(INDEX(Location!X:X, MATCH(BS11, Location!W:W, 0)), "") | S11: 1003446782 | T11: https://prod-clinicians-photo.s3.amazonaws.com/1003446782.jpg | U11: PsyD, Adler University | Z11: Dr. Naylon is a clinical neuropsychologist who provides comprehensive neuropsychological evaluations and treatment for adults with a wide range of neurological, neurodegenerative, medical, and psychological conditions and complications that impact cognitive functioning. Evaluations consist of an indepth clinical interview to obtain a thorough and unique understanding of each individual, their background, and their presenting concerns followed by comprehensive neuropsychological testing. Assessment results are interpreted in the context of each individualâs unique circumstances. Feedback on results and interpretation is provided to patients and includes detailed descriptions of strengths and weaknesses, diagnostic impressions and implications, and tailored recommendations to ameliorate presenting concerns and improve daily life experience. Dr. Naylonâs clinical interests include neurodegenerative and neurological conditions dementia, movement disorders, epilepsy, multiple sclerosis, etc., complex medical complicationsconditions and impact on cognition, the impact of sleep and psychological symptomsconditions on cognition, eating disorders, traumatic brain injury, and stroke. Dr. Naylon provides more indepth intervention and treatment to facilitate implementation of tailored recommendations yielded from neuropsychological evaluations. She provides cognitive rehabilitation therapy to help patients capitalize on cognitive strengths and ameliorate weaknesses. She also provides cognitive behavioral therapy for insomnia to improve sleep and, subsequently, cognitive and mood symptoms. Dr. Naylon received her bachelorâs degree in Biology and Psychology from John Carroll University. She received her doctoral degree in Clinical Psychology with specialization in Neuropsychology from Adler University. She completed a predoctoral internship in Clinical Neuropsychology at the VA North Texas Healthcare System and a twoyear fellowship in Clinical Neuropsychology at the University of Massachusetts Medical School. | AZ11: English | BC11: pt_B8LtUoRcYkWdny_20xbxdB | BE11: Practitioner - Full Profile | BG11: No | BI11: =IFERROR(INDEX(ValidationAndReference!P:P, MATCH(BE11, ValidationAndReference!Q:Q, 0)), "") | BJ11: =IFERROR(INDEX(ValidationAndReference!F:F, MATCH(D11, ValidationAndReference!G:G, 0)), "") | BK11: =IFERROR(INDEX(ValidationAndReference!F:F, MATCH(E11, ValidationAndReference!G:G, 0)), "") | BL11: =IFERROR(INDEX(ValidationAndReference!F:F, MATCH(F11, ValidationAndReference!G:G, 0)), "") | BM11: 337 | BR11: lo_Gu1H1AlMKkGM7YEE-cV0Mx | BS11: lo_SgGZ9ru7iU62TuMizXbvrx | CL11: =IFERROR(INDEX(ValidationAndReference!V:V, MATCH(AZ11, ValidationAndReference!W:W, 0)), "") | CM11: =IFERROR(INDEX(ValidationAndReference!V:V, MATCH(BA11, ValidationAndReference!W:W, 0)), "") | CN11: =IFERROR(INDEX(ValidationAndReference!V:V, MATCH(BB11, ValidationAndReference!W:W, 0)), "") | CO11: 185 Devonshire St | CP11: Boston | CQ11: 2110 | CR11: MA | CT11: No - Facility Zip
A12: Enid | B12: Levangie | C12: Female | D12: MSW | E12: LCSW | G12: =IFERROR(VLOOKUP(BM12, ValidationAndReference!J:K, 2, FALSE), "") | L12: Both | M12: LifeStance Health | N12: =IFERROR(INDEX(Location!X:X, MATCH(BR12, Location!W:W, 0)), "") | O12: =IFERROR(INDEX(Location!X:X, MATCH(BS12, Location!W:W, 0)), "") | S12: 1003694183 | T12: https://prod-clinicians-photo.s3.amazonaws.com/1003694183.jpg | U12: MSW, Simmons University | Z12: Enid Levangie is a Licensed Clinical Social Worker in Massachusetts who has been practicing since 2023. She obtained her Masterâs in Social Work from Simmons University and her Bachelorâs in psychology from Michigan State University. Enid sees children, adolescents, young adults, and adults individually as well as families and groups. She works with clients who are experiencing a wide range of issues, including depression, anxiety, traumaPTSD, and selfesteem. Enid uses a strengthbased, personcentered, and holistic approach, which is designed to meet clients where they are and provide a safe and comfortable space to help clients explore areas they want to work on in treatment and to learn and grow in ways that will improve their overall wellbeing. Enid uses many different theories and modalities in her treatment approach that include, but are not limited to personcentered therapy, cognitive behavioral therapy, Narrative therapy, Solutionfocused therapy, motivational interviewing, EMDR, and mindfulness and meditation. In her free time, Enid enjoys hiking, running, yoga, reading, and paddle boarding. | AZ12: English | BC12: pt_B8LtUoRcYkWdny_20xbxdB | BE12: Practitioner - Full Profile | BG12: No | BI12: =IFERROR(INDEX(ValidationAndReference!P:P, MATCH(BE12, ValidationAndReference!Q:Q, 0)), "") | BJ12: =IFERROR(INDEX(ValidationAndReference!F:F, MATCH(D12, ValidationAndReference!G:G, 0)), "") | BK12: =IFERROR(INDEX(ValidationAndReference!F:F, MATCH(E12, ValidationAndReference!G:G, 0)), "") | BL12: =IFERROR(INDEX(ValidationAndReference!F:F, MATCH(F12, ValidationAndReference!G:G, 0)), "") | BM12: 352 | BR12: lo_lEHs7EV-Q0q1ZVBScjqtKx | BS12: lo_Anm_Viii6U65HIuJ7sGPah | CL12: =IFERROR(INDEX(ValidationAndReference!V:V, MATCH(AZ12, ValidationAndReference!W:W, 0)), "") | CM12: =IFERROR(INDEX(ValidationAndReference!V:V, MATCH(BA12, ValidationAndReference!W:W, 0)), "") | CN12: =IFERROR(INDEX(ValidationAndReference!V:V, MATCH(BB12, ValidationAndReference!W:W, 0)), "") | CO12: 288 Walnut St | CP12: Newton | CQ12: 2460 | CR12: MA | CT12: No - Facility Zip
A13: Christopher | B13: Welch | C13: Male | D13: PsyD | E13: LCP | G13: =IFERROR(VLOOKUP(BM13, ValidationAndReference!J:K, 2, FALSE), "") | L13: Both | M13: LifeStance Health | N13: =IFERROR(INDEX(Location!X:X, MATCH(BR13, Location!W:W, 0)), "") | O13: =IFERROR(INDEX(Location!X:X, MATCH(BS13, Location!W:W, 0)), "") | S13: 1013039809 | T13: https://prod-clinicians-photo.s3.amazonaws.com/1013039809.jpg | U13: PsyD, Georgia School of Professional Psychology | Z13: Dr. Welch utilizes a curious, empathic, encouraging and pragmatic style to therapy with adolescents and adults who are experiencing challenges related to depressionanger, mood, anxiety and trauma, family conflict, and emotional regulationbehavioral control. He has a particular interest and specializes in assisting individuals who are in the process of negotiating the myriad changes associated with transitions that occur during adolescence through early adulthood, such as individuation, perceived inadequacyimpostor syndrome, identity confusion and relationship concerns. He often employs stress reduction and relaxation techniques, cognitivebehavioral therapy CBT and mindfulness approaches, notably Acceptance and Commitment Therapy ACT, to foster the development and application of skills that help clients to realize the changes they desire. | AZ13: English | BC13: pt_B8LtUoRcYkWdny_20xbxdB | BE13: Practitioner - Full Profile | BG13: No | BI13: =IFERROR(INDEX(ValidationAndReference!P:P, MATCH(BE13, ValidationAndReference!Q:Q, 0)), "") | BJ13: =IFERROR(INDEX(ValidationAndReference!F:F, MATCH(D13, ValidationAndReference!G:G, 0)), "") | BK13: =IFERROR(INDEX(ValidationAndReference!F:F, MATCH(E13, ValidationAndReference!G:G, 0)), "") | BL13: =IFERROR(INDEX(ValidationAndReference!F:F, MATCH(F13, ValidationAndReference!G:G, 0)), "") | BM13: 337 | BR13: lo_HsSHXkMbXkmjKV9DTQwrRg | BS13: lo_X1n8nk7odk6kG9Qth0jnUR | CL13: =IFERROR(INDEX(ValidationAndReference!V:V, MATCH(AZ13, ValidationAndReference!W:W, 0)), "") | CM13: =IFERROR(INDEX(ValidationAndReference!V:V, MATCH(BA13, ValidationAndReference!W:W, 0)), "") | CN13: =IFERROR(INDEX(ValidationAndReference!V:V, MATCH(BB13, ValidationAndReference!W:W, 0)), "") | CO13: 22 Ml St | CP13: Arlington | CQ13: 2476 | CR13: MA | CT13: No - Facility Address (try converting 'Ml' to 'MILL'; try converting 'St' to 'ST'; try converting 'St' to 'STREET'; try converting 'St' to 'STRT'; try converting 'St' to 'ST'; try converting 'St' to 'STR'), Facility Zip
A14: Melanie | B14: Blount | C14: Female | D14: PhD | E14: LP | G14: =IFERROR(VLOOKUP(BM14, ValidationAndReference!J:K, 2, FALSE), "") | L14: Adult | M14: LifeStance Health | N14: =IFERROR(INDEX(Location!X:X, MATCH(BR14, Location!W:W, 0)), "") | O14: =IFERROR(INDEX(Location!X:X, MATCH(BS14, Location!W:W, 0)), "") | S14: 1013103589 | T14: https://prod-clinicians-photo.s3.amazonaws.com/1013103589.jpg | U14: PsyD, Massachusetts School of Professional Psychology | Z14: Dr. Blount is a licensed psychologist offering individual psychotherapy for adults and adolescents as well as assistance for parents with infants struggling with attachment concerns. Her clinical interests include treatment of postpartum concerns, depression, anxiety, griefloss, and traumaPTSD. Dr. Blount integrates various therapeutic approaches based on what suits each clientâs needs best. Attachment theory guides much of her conceptual understanding, and she utilizes cognitivebehavioral, psychodynamic, and relational approaches depending on the clientâs needs. She believes that the therapeutic relationship â namely the trust, genuineness, and warmth between the therapist and client â is of most importance in having treatment be successful and is the foundation through which change can occur. Dr. Blount earned her doctorate in clinical psychology from William James College and her Masterâs in psychology in education from Columbia University. She completed an APAaccredited predoctoral internship and postdoctoral fellowship at Lynn Community Health Center in Lynn, MA. She has worked with a variety of adults, adolescents, and children within community clinics, school based health centers, and private practice. | AZ14: English | BC14: pt_B8LtUoRcYkWdny_20xbxdB | BE14: Practitioner - Full Profile | BG14: No | BI14: =IFERROR(INDEX(ValidationAndReference!P:P, MATCH(BE14, ValidationAndReference!Q:Q, 0)), "") | BJ14: =IFERROR(INDEX(ValidationAndReference!F:F, MATCH(D14, ValidationAndReference!G:G, 0)), "") | BK14: =IFERROR(INDEX(ValidationAndReference!F:F, MATCH(E14, ValidationAndReference!G:G, 0)), "") | BL14: =IFERROR(INDEX(ValidationAndReference!F:F, MATCH(F14, ValidationAndReference!G:G, 0)), "") | BM14: 337 | BR14: lo_yG3WQGVBVUynSkFssssbHg | CL14: =IFERROR(INDEX(ValidationAndReference!V:V, MATCH(AZ14, ValidationAndReference!W:W, 0)), "") | CM14: =IFERROR(INDEX(ValidationAndReference!V:V, MATCH(BA14, ValidationAndReference!W:W, 0)), "") | CN14: =IFERROR(INDEX(ValidationAndReference!V:V, MATCH(BB14, ValidationAndReference!W:W, 0)), "") | CO14: 625 Mt Auburn St | CP14: Cambridge | CQ14: 2138 | CR14: MA | CT14: No - Facility Zip
A15: William | B15: Sutton-Ohannesian | C15: Male | D15: DNP | E15: PMHNP-BC | G15: =IFERROR(VLOOKUP(BM15, ValidationAndReference!J:K, 2, FALSE), "") | L15: Both | M15: LifeStance Health | N15: =IFERROR(INDEX(Location!X:X, MATCH(BR15, Location!W:W, 0)), "") | O15: =IFERROR(INDEX(Location!X:X, MATCH(BS15, Location!W:W, 0)), "") | S15: 1013261965 | T15: https://prod-clinicians-photo.s3.amazonaws.com/1013261965.jpg | U15: DNP, University of Maryland Baltimore County | Z15: Dr. Will SuttonOhannesian is a Psychiatric Mental Health Nurse Practitioner in Massachusetts who has been practicing since 2018. He holds a Doctorate in Nursing Practice from the University of Maryland and a BSN from Boston College. Dr. SuttonOhannesian provides medication management, brief psychotherapy, and psychoeducation. He is experienced with patients with various psychiatric disorders including refractory depression, schizoaffective disorder, and gender dysphoria. Dr. SuttonOhannesian has practiced in emergency psychiatry, nursing homes, assisted living facilities, as well as outpatient practice locations, and has a history of providing TMS treatments and has assisted with ECT. Outside of work, Dr. SuttonOhannesian is a collector, a pianist, and enjoys spending time with his cats. | AZ15: English | BA15: Spanish | BC15: pt_B8LtUoRcYkWdny_20xbxdB | BE15: Practitioner - Full Profile | BG15: No | BI15: =IFERROR(INDEX(ValidationAndReference!P:P, MATCH(BE15, ValidationAndReference!Q:Q, 0)), "") | BJ15: =IFERROR(INDEX(ValidationAndReference!F:F, MATCH(D15, ValidationAndReference!G:G, 0)), "") | BK15: =IFERROR(INDEX(ValidationAndReference!F:F, MATCH(E15, ValidationAndReference!G:G, 0)), "") | BL15: =IFERROR(INDEX(ValidationAndReference!F:F, MATCH(F15, ValidationAndReference!G:G, 0)), "") | BM15: 405 | BR15: lo_n8Umo4IPt0OAdtKpVzV4Eg | CL15: =IFERROR(INDEX(ValidationAndReference!V:V, MATCH(AZ15, ValidationAndReference!W:W, 0)), "") | CM15: =IFERROR(INDEX(ValidationAndReference!V:V, MATCH(BA15, ValidationAndReference!W:W, 0)), "") | CN15: =IFERROR(INDEX(ValidationAndReference!V:V, MATCH(BB15, ValidationAndReference!W:W, 0)), "") | CO15: 4 Collins Ave | CP15: Plymouth | CQ15: 2360 | CR15: MA | CT15: No - Facility Zip
A16: Michael | B16: Wiehe | C16: Male | D16: MSW | E16: LICSW | G16: =IFERROR(VLOOKUP(BM16, ValidationAndReference!J:K, 2, FALSE), "") | L16: Adult | M16: LifeStance Health | N16: =IFERROR(INDEX(Location!X:X, MATCH(BR16, Location!W:W, 0)), "") | O16: =IFERROR(INDEX(Location!X:X, MATCH(BS16, Location!W:W, 0)), "") | S16: 1013295930 | T16: https://prod-clinicians-photo.s3.amazonaws.com/1013295930.jpg | U16: MSW, San Diego State University | Z16: Michael Wiehe provides evidence based psychotherapy and treatment for adults suffering from mood disorders, depression and anxiety. He utilizes cognitive behavior therapy CBT as a primary approach, along with with aspects of solution focused treatment and motivational interviewing. After completing his Masters degree in 2011, Michael joined South Bay Mental Health as a therapist on the dualdiagnoses team. He took a concurrent position as a group facilitator at South Bay Day Servicesâ partial hospitalization program where he ran groups for the PHP and IOP programs. Following his time at South Bay, he worked as an outpatient therapist at Wilmington Family counseling for three years, with a focus on mood disorders and dual diagnosis. Before joining LifeStance in 2020, Mr. Wiehe was the Clinical Director of Arbour Counselingâs Partial Hospitalization Program in Woburn, starting in 2017, after working as a group facilitator at that program. Mr. Wiehe joins our Woburn office, where he provides assessment and treatment for the adult population. | AZ16: English | BC16: pt_B8LtUoRcYkWdny_20xbxdB | BE16: Practitioner - Full Profile | BG16: No | BI16: =IFERROR(INDEX(ValidationAndReference!P:P, MATCH(BE16, ValidationAndReference!Q:Q, 0)), "") | BJ16: =IFERROR(INDEX(ValidationAndReference!F:F, MATCH(D16, ValidationAndReference!G:G, 0)), "") | BK16: =IFERROR(INDEX(ValidationAndReference!F:F, MATCH(E16, ValidationAndReference!G:G, 0)), "") | BL16: =IFERROR(INDEX(ValidationAndReference!F:F, MATCH(F16, ValidationAndReference!G:G, 0)), "") | BM16: 352 | BR16: lo_OVMZ6PsRXEqHzEFN4lLt_A | BS16: lo_ayvzZmw2UU2gH1k_iwnvJB | CL16: =IFERROR(INDEX(ValidationAndReference!V:V, MATCH(AZ16, ValidationAndReference!W:W, 0)), "") | CM16: =IFERROR(INDEX(ValidationAndReference!V:V, MATCH(BA16, ValidationAndReference!W:W, 0)), "") | CN16: =IFERROR(INDEX(ValidationAndReference!V:V, MATCH(BB16, ValidationAndReference!W:W, 0)), "") | CO16: 12 Alfred St | CP16: Woburn | CQ16: 1801 | CR16: MA | CT16: No - Facility Zip
A17: Julie | B17: West | C17: Female | D17: DNP | E17: PMHNP-BC | G17: =IFERROR(VLOOKUP(BM17, ValidationAndReference!J:K, 2, FALSE), "") | L17: Both | M17: LifeStance Health | N17: =IFERROR(INDEX(Location!X:X, MATCH(BR17, Location!W:W, 0)), "") | O17: =IFERROR(INDEX(Location!X:X, MATCH(BS17, Location!W:W, 0)), "") | S17: 1013527423 | T17: https://prod-clinicians-photo.s3.amazonaws.com/1013527423.jpg | U17: DNP, Columbia University School of Nursing | Z17: Julie West, NP, PMHNP, is a dedicated psychiatric nurse practitioner at LifeStance Health who provides compassionate, evidencebased care to individuals across Massachusetts. Serving adults and seniors, Julie helps patients navigate complex mental health challenges through individualized psychiatric evaluations, accurate diagnoses, and tailored treatment plans. By focusing on the biological, psychological, and social factors that contribute to mental health disorders, she strives to empower her patients on their path to healing. Julie is particularly passionate about supporting patients with anxiety, depression, and PTSD. She has a strong focus on addressing reproductive challenges and postpartum depressionanxiety, as well as helping individuals facing midlife and laterlife transitions. With a deep understanding of the unique needs these experiences present, Julie takes a holistic, collaborative approach to treatment, ensuring her patients feel supported every step of the way. She integrates psychotherapy and medication management to promote longlasting positive change. In addition to her specialized focus on womenâs issues and reproductive mental health, Julie is experienced in treating substance use disorders, psychosis, and traumarelated conditions. She is committed to helping military veterans, first responders, and individuals in the LGBTQ community overcome mental health challenges and achieve greater emotional wellbeing. Julies approach prioritizes the development of trusting, therapeutic relationships, allowing patients to openly share their concerns and work towards a healthier, more fulfilling life. Outside of her clinical work, Julie enjoys spending time with her family and dogs, embracing the outdoors when the weather allows, and indulging in a cozy pajama day indoors every once in a while. Her balance of professional dedication and personal selfcare enhances her ability to provide thoughtful and compassionate mental health care. Julie West is committed to serving patients across Massachusetts, helping them achieve their mental health goals through comprehensive, individualized care. | AZ17: English | BC17: pt_B8LtUoRcYkWdny_20xbxdB | BE17: Practitioner - Full Profile | BG17: No | BI17: =IFERROR(INDEX(ValidationAndReference!P:P, MATCH(BE17, ValidationAndReference!Q:Q, 0)), "") | BJ17: =IFERROR(INDEX(ValidationAndReference!F:F, MATCH(D17, ValidationAndReference!G:G, 0)), "") | BK17: =IFERROR(INDEX(ValidationAndReference!F:F, MATCH(E17, ValidationAndReference!G:G, 0)), "") | BL17: =IFERROR(INDEX(ValidationAndReference!F:F, MATCH(F17, ValidationAndReference!G:G, 0)), "") | BM17: 405 | BR17: lo_L3CIiVDHYESqWdC6bOuAqh | BS17: lo_bn7sE2w_SkyP7nJ0v5wixh | CL17: =IFERROR(INDEX(ValidationAndReference!V:V, MATCH(AZ17, ValidationAndReference!W:W, 0)), "") | CM17: =IFERROR(INDEX(ValidationAndReference!V:V, MATCH(BA17, ValidationAndReference!W:W, 0)), "") | CN17: =IFERROR(INDEX(ValidationAndReference!V:V, MATCH(BB17, ValidationAndReference!W:W, 0)), "") | CO17: 110 Hartwell Ave | CP17: Lexington | CQ17: 2421 | CR17: MA | CT17: No - Facility Zip
A18: Patricia | B18: Donahue Kennedy | C18: Female | D18: MSW | E18: LICSW | G18: =IFERROR(VLOOKUP(BM18, ValidationAndReference!J:K, 2, FALSE), "") | L18: Both | M18: LifeStance Health | N18: =IFERROR(INDEX(Location!X:X, MATCH(BR18, Location!W:W, 0)), "") | O18: =IFERROR(INDEX(Location!X:X, MATCH(BS18, Location!W:W, 0)), "") | S18: 1033288196 | T18: https://prod-clinicians-photo.s3.amazonaws.com/1033288196.jpg | U18: MSSW, Boston University | Z18: LICSW specializing in children and teenagers. I received my Masters in Social Work from Boston University in 2006. I have been working with children and families for over 20 years. I practice psychotherapy methods of CBT and play therapy. I am able to connect with children and am able to easily engage my clients. I use humor in my work and play therapy as well as mindfulness. I have a vast amount of experience in working as a clinical therapist in many settings through out the span of my career. I enjoy working with clients and helping them in with their emotional and mental health. | AZ18: English | BC18: pt_B8LtUoRcYkWdny_20xbxdB | BE18: Practitioner - Full Profile | BG18: No | BI18: =IFERROR(INDEX(ValidationAndReference!P:P, MATCH(BE18, ValidationAndReference!Q:Q, 0)), "") | BJ18: =IFERROR(INDEX(ValidationAndReference!F:F, MATCH(D18, ValidationAndReference!G:G, 0)), "") | BK18: =IFERROR(INDEX(ValidationAndReference!F:F, MATCH(E18, ValidationAndReference!G:G, 0)), "") | BL18: =IFERROR(INDEX(ValidationAndReference!F:F, MATCH(F18, ValidationAndReference!G:G, 0)), "") | BM18: 352 | BR18: lo_WGSx6xN8302ASv6YVggXbh | BS18: lo_8kwZD7BrWkmw6LTpfZ-4yB | CL18: =IFERROR(INDEX(ValidationAndReference!V:V, MATCH(AZ18, ValidationAndReference!W:W, 0)), "") | CM18: =IFERROR(INDEX(ValidationAndReference!V:V, MATCH(BA18, ValidationAndReference!W:W, 0)), "") | CN18: =IFERROR(INDEX(ValidationAndReference!V:V, MATCH(BB18, ValidationAndReference!W:W, 0)), "") | CO18: 175 Paramount Dr | CP18: Raynham | CQ18: 2767 | CR18: MA | CT18: No - Facility Zip
A19: Patricia | B19: Donahue Kennedy | C19: Female | D19: MSW | E19: LICSW | G19: =IFERROR(VLOOKUP(BM19, ValidationAndReference!J:K, 2, FALSE), "") | L19: Both | M19: LifeStance Health | N19: =IFERROR(INDEX(Location!X:X, MATCH(BR19, Location!W:W, 0)), "") | O19: =IFERROR(INDEX(Location!X:X, MATCH(BS19, Location!W:W, 0)), "") | S19: 1033288196 | T19: https://prod-clinicians-photo.s3.amazonaws.com/1033288196.jpg | U19: MSSW, Boston University | Z19: LICSW specializing in children and teenagers. I received my Masters in Social Work from Boston University in 2006. I have been working with children and families for over 20 years. I practice psychotherapy methods of CBT and play therapy. I am able to connect with children and am able to easily engage my clients. I use humor in my work and play therapy as well as mindfulness. I have a vast amount of experience in working as a clinical therapist in many settings through out the span of my career. I enjoy working with clients and helping them in with their emotional and mental health. | AZ19: English | BC19: pt_B8LtUoRcYkWdny_20xbxdB | BE19: Practitioner - Full Profile | BG19: No | BI19: =IFERROR(INDEX(ValidationAndReference!P:P, MATCH(BE19, ValidationAndReference!Q:Q, 0)), "") | BJ19: =IFERROR(INDEX(ValidationAndReference!F:F, MATCH(D19, ValidationAndReference!G:G, 0)), "") | BK19: =IFERROR(INDEX(ValidationAndReference!F:F, MATCH(E19, ValidationAndReference!G:G, 0)), "") | BL19: =IFERROR(INDEX(ValidationAndReference!F:F, MATCH(F19, ValidationAndReference!G:G, 0)), "") | BM19: 352 | BR19: lo_WGSx6xN8302ASv6YVggXbh | BS19: lo_8kwZD7BrWkmw6LTpfZ-4yB | CL19: =IFERROR(INDEX(ValidationAndReference!V:V, MATCH(AZ19, ValidationAndReference!W:W, 0)), "") | CM19: =IFERROR(INDEX(ValidationAndReference!V:V, MATCH(BA19, ValidationAndReference!W:W, 0)), "") | CN19: =IFERROR(INDEX(ValidationAndReference!V:V, MATCH(BB19, ValidationAndReference!W:W, 0)), "") | CO19: 175 Paramount Dr | CP19: Raynham | CQ19: 2767 | CR19: MA | CT19: No - Facility Zip
A20: Allison | B20: Moore | C20: Female | D20: MSW | E20: LICSW | G20: =IFERROR(VLOOKUP(BM20, ValidationAndReference!J:K, 2, FALSE), "") | L20: Both | M20: LifeStance Health | N20: =IFERROR(INDEX(Location!X:X, MATCH(BR20, Location!W:W, 0)), "") | O20: =IFERROR(INDEX(Location!X:X, MATCH(BS20, Location!W:W, 0)), "") | S20: 1033808506 | T20: https://prod-clinicians-photo.s3.amazonaws.com/1033808506.jpg | U20: MSW, University of New Hampshire- Durham | Z20: Allison Moore is a Licensed Independent Clinical Social Worker in New Hampshire who has been practicing since 2018. She has a Master of Social Work and a Masters of Business Administration. Allison helps clients navigating the changes and challenges that life brings, including starting at a new job or school, changes in independence, relationship concerns, lifestyle changes, and building a family. She is passionate about interpersonal skill building, improvement of selfesteem, navigating difficult relationships, making long term lifestyle changes, and selfregulation. Outside of work, Allison enjoys spending time with her family, being an outdoor enthusiast, hiking, biking, spending time with her dogs, and camping. | AZ20: English | BC20: pt_B8LtUoRcYkWdny_20xbxdB | BE20: Practitioner - Full Profile | BG20: No | BI20: =IFERROR(INDEX(ValidationAndReference!P:P, MATCH(BE20, ValidationAndReference!Q:Q, 0)), "") | BJ20: =IFERROR(INDEX(ValidationAndReference!F:F, MATCH(D20, ValidationAndReference!G:G, 0)), "") | BK20: =IFERROR(INDEX(ValidationAndReference!F:F, MATCH(E20, ValidationAndReference!G:G, 0)), "") | BL20: =IFERROR(INDEX(ValidationAndReference!F:F, MATCH(F20, ValidationAndReference!G:G, 0)), "") | BM20: 352 | BR20: lo_3hIK25O-lEqM6hnbD-8HXh | BS20: lo_y_6qaxOiQUSFScBKd0V0Dh | CL20: =IFERROR(INDEX(ValidationAndReference!V:V, MATCH(AZ20, ValidationAndReference!W:W, 0)), "") | CM20: =IFERROR(INDEX(ValidationAndReference!V:V, MATCH(BA20, ValidationAndReference!W:W, 0)), "") | CN20: =IFERROR(INDEX(ValidationAndReference!V:V, MATCH(BB20, ValidationAndReference!W:W, 0)), "") | CO20: 120 Boston Rd | CP20: Groton | CQ20: 1450 | CR20: MA | CS20: Ste 200 | CT20: No - Facility Zip
A21: Anniken | B21: Genova | C21: Female | D21: MA | E21: LMHC | G21: =IFERROR(VLOOKUP(BM21, ValidationAndReference!J:K, 2, FALSE), "") | L21: Both | M21: LifeStance Health | N21: =IFERROR(INDEX(Location!X:X, MATCH(BR21, Location!W:W, 0)), "") | O21: =IFERROR(INDEX(Location!X:X, MATCH(BS21, Location!W:W, 0)), "") | S21: 1033926993 | T21: https://prod-clinicians-photo.s3.amazonaws.com/1033926993.jpg | U21: MA, Framingham State University | Z21: Anniken Genova, LMHC, is a compassionate therapist at LifeStance Health, providing individual therapy to adolescents and adults in Massachusetts. She is dedicated to creating a supportive, nonjudgmental space where clients can explore their thoughts, emotions, and behaviors. Whether struggling with anxiety, depression, mood disorders, or trauma, Anniken helps clients develop coping strategies to foster resilience and personal growth. She tailors treatment to each individualâs needs, ensuring they feel heard and empowered throughout their healing process. Anniken specializes in treating anxiety, PTSDtrauma, and depression, offering evidencebased interventions to support clients facing these challenges. She understands the complex impact of trauma and anxietyrelated disorders on daily life and works closely with clients to address their symptoms in a meaningful way. Her approach integrates Cognitive Behavioral Therapy CBT, Dialectical Behavior Therapy DBT, and Acceptance & Commitment Therapy ACT, equipping clients with practical tools to navigate distress, regulate emotions, and improve overall wellbeing. In addition to her primary specialties, Anniken has a strong focus on supporting womenâs mental health, including postpartum depression and anxiety, midlife transitions, and personal identity struggles. She also provides guidance for individuals navigating adoption and foster care experiences. Her empathetic and collaborative approach allows clients to work through lifeâs challenges with confidence and selfcompassion. Outside of her practice, Anniken enjoys spending time with her family, hiking, traveling, knitting, and soaking up the sun at the beach. | AZ21: English | BA21: Norwegian | BC21: pt_B8LtUoRcYkWdny_20xbxdB | BE21: Practitioner - Full Profile | BG21: No | BI21: =IFERROR(INDEX(ValidationAndReference!P:P, MATCH(BE21, ValidationAndReference!Q:Q, 0)), "") | BJ21: =IFERROR(INDEX(ValidationAndReference!F:F, MATCH(D21, ValidationAndReference!G:G, 0)), "") | BK21: =IFERROR(INDEX(ValidationAndReference!F:F, MATCH(E21, ValidationAndReference!G:G, 0)), "") | BL21: =IFERROR(INDEX(ValidationAndReference!F:F, MATCH(F21, ValidationAndReference!G:G, 0)), "") | BM21: 352 | BR21: lo_J3bUpmaXpUWalQ11VmCr4R | BS21: lo_-ThUCWj4EkKTcIpHZ58qdB | CL21: =IFERROR(INDEX(ValidationAndReference!V:V, MATCH(AZ21, ValidationAndReference!W:W, 0)), "") | CM21: =IFERROR(INDEX(ValidationAndReference!V:V, MATCH(BA21, ValidationAndReference!W:W, 0)), "") | CN21: =IFERROR(INDEX(ValidationAndReference!V:V, MATCH(BB21, ValidationAndReference!W:W, 0)), "") | CO21: 25 Birch St | CP21: Milford | CQ21: 1757 | CR21: MA | CT21: No - Facility Zip
