Workbook

Sheet Provider
A1: First Name | B1: Last Name | C1: Gender | D1: Professional Suffix 1 | E1: Professional Suffix 2 | F1: Professional Suffix 3 | G1: Specialty 1 | H1: Specialty 2 | I1: Specialty 3 | J1: Specialty 4 | K1: Specialty 5 | L1: Patients Accepted | M1: Practice Name | N1: Location 1 | O1: Location 2 | P1: Location 3 | Q1: Location 4 | R1: Location 5 | S1: NPI Number | T1: Headshot Link | U1: Education 1 | V1: Education 2 | W1: Education 3 | X1: Education 4 | Y1: Education 5 | Z1: Professional Statement | AA1: Board Certification 1 | AB1: Sub Board Certification 1 | AC1: Board Certification 2 | AD1: Sub Board Certification 2 | AE1: Board Certification 3 | AF1: Sub Board Certification 3 | AG1: Board Certification 4 | AH1: Sub Board Certification 4 | AI1: Board Certification 5 | AJ1: Sub Board Certification 5 | AK1: Professional Memberships 1 | AL1: Professional Memberships 2 | AM1: Professional Memberships 3 | AN1: Professional Memberships 4 | AO1: Professional Memberships 5 | AP1: Awards and Publications 1 | AQ1: Awards and Publications 2 | AR1: Awards and Publications 3 | AS1: Awards and Publications 4 | AT1: Awards and Publications 5 | AU1: Hospital Affiliation 1 | AV1: Hospital Affiliation 2 | AW1: Hospital Affiliation 3 | AX1: Hospital Affiliation 4 | AY1: Hospital Affiliation 5 | AZ1: Additional Languages Spoken 1 | BA1: Additional Languages Spoken 2 | BB1: Additional Languages Spoken 3 | BC1: Practice Cloud ID | BD1: Provider Cloud ID | BE1: Provider Type | BF1: Salesforce Contact ID | BG1: Enterprise Scheduling Flag | BH1: Opt Out of Ratings | BI1: Provider Type (Substatus) ID | BJ1: Professional Suffix ID 1 | BK1: Professional Suffix ID 2 | BL1: Professional Suffix ID 3 | BM1: Specialty ID 1 | BN1: Specialty ID 2 | BO1: Specialty ID 3 | BP1: Specialty ID 4 | BQ1: Specialty ID 5 | BR1: Location ID 1 | BS1: Location ID 2 | BT1: Location ID 3 | BU1: Location ID 4 | BV1: Location ID 5 | BW1: Board Cert ID 1 | BX1: Sub Board Cert ID 1 | BY1: Board Cert ID 2 | BZ1: Sub Board Cert ID 2 | CA1: Board Cert ID 3 | CB1: Sub Board Cert ID 3 | CC1: Board Cert ID 4 | CD1: Sub Board Cert ID 4 | CE1: Board Cert ID 5 | CF1: Sub Board Cert ID 5 | CG1: Hospital Affiliation ID 1 | CH1: Hospital Affiliation ID 2 | CI1: Hospital Affiliation ID 3 | CJ1: Hospital Affiliation ID 4 | CK1: Hospital Affiliation ID 5 | CL1: Language ID 1 | CM1: Language ID 2 | CN1: Language ID 3 | CO1: Facility Address | CP1: Facility City | CQ1: Facility Zip | CR1: Facility State | CS1: Address line 2 | CT1: Matched
A2: Rachel | B2: Fitch | C2: Female | D2: DSW | E2: LISW-S | F2: LCSW | G2: =IFERROR(VLOOKUP(BM2, ValidationAndReference!J:K, 2, FALSE), "") | L2: Both | M2: LifeStance Health | N2: =IFERROR(INDEX(Location!X:X, MATCH(BR2, Location!W:W, 0)), "") | O2: =IFERROR(INDEX(Location!X:X, MATCH(BS2, Location!W:W, 0)), "") | S2: 1013105469 | T2: https://prod-clinicians-photo.s3.amazonaws.com/1013105469.jpg | U2: Doctor of Social Work (DSW), University of Kentucky | Z2: Rachel Fitch, LCSW, helps individuals and families across Ohio find healing, hope, and renewed purpose through compassionate, evidencebased care. She works with adolescents, teens, and adults to navigate lifeâs most difficult challenges, including anxiety, depression, relationship struggles, and trauma. Rachel believes that therapy is a collaborative journeyâone that empowers clients to develop greater selfunderstanding, improve communication, and create lasting emotional balance. Rachel provides individual, couples, and family therapy at LifeStance Health, integrating Cognitive Behavioral Therapy CBT, mindfulness, and familybased approaches to support growth and resilience. She is experienced in helping clients facing complex concerns such as ADHD, postpartum depression, PTSDtrauma, and womenâs issues. Her approach combines clinical expertise with genuine warmth, allowing clients to feel supported and understood as they work toward their goals. Rachel is especially passionate about supporting individuals who have recently been discharged from a psychiatric hospital, helping them transition safely and confidently back into daily life. She offers structured guidance and emotional support to promote stability, reduce relapse risk, and strengthen coping skills. Rachel also works extensively with clinicians, first responders, and child welfare professionals experiencing burnout or secondary trauma, helping them rediscover balance and meaning in their personal and professional lives. Her practice welcomes diverse populations, including members of the LGBTQ community, military personnel and veterans, women, and individuals from adoption or foster care backgrounds. Rachelâs dedication to traumainformed and inclusive care ensures that every client feels seen and valued. Outside of her clinical work, Rachel enjoys reading, DIY home projects with her husband, and spending time with their two dogs. These personal passions reflect her belief in creating comfort, connection, and creativityâboth in her home and in her therapeutic work. | AZ2: English | BC2: pt_5pmdAWg-0UuZBxgghGIfih | BE2: Practitioner - Full Profile | BG2: No | BI2: =IFERROR(INDEX(ValidationAndReference!P:P, MATCH(BE2, ValidationAndReference!Q:Q, 0)), "") | BJ2: =IFERROR(INDEX(ValidationAndReference!F:F, MATCH(D2, ValidationAndReference!G:G, 0)), "") | BK2: =IFERROR(INDEX(ValidationAndReference!F:F, MATCH(E2, ValidationAndReference!G:G, 0)), "") | BL2: =IFERROR(INDEX(ValidationAndReference!F:F, MATCH(F2, ValidationAndReference!G:G, 0)), "") | BM2: 352 | BR2: lo_Co2PtuT10kC3DHSCyaUKPh | CL2: =IFERROR(INDEX(ValidationAndReference!V:V, MATCH(AZ2, ValidationAndReference!W:W, 0)), "") | CM2: =IFERROR(INDEX(ValidationAndReference!V:V, MATCH(BA2, ValidationAndReference!W:W, 0)), "") | CN2: =IFERROR(INDEX(ValidationAndReference!V:V, MATCH(BB2, ValidationAndReference!W:W, 0)), "") | CO2: 1077 State Rte 28 | CP2: Milford | CQ2: 45150 | CR2: OH | CS2: Ste 202 | CT2: No - Facility Zip
A3: Rachel | B3: Fitch | C3: Female | D3: DSW | E3: LISW-S | F3: LCSW | G3: =IFERROR(VLOOKUP(BM3, ValidationAndReference!J:K, 2, FALSE), "") | L3: Both | M3: LifeStance Health | N3: =IFERROR(INDEX(Location!X:X, MATCH(BR3, Location!W:W, 0)), "") | O3: =IFERROR(INDEX(Location!X:X, MATCH(BS3, Location!W:W, 0)), "") | S3: 1013105469 | T3: https://prod-clinicians-photo.s3.amazonaws.com/1013105469.jpg | U3: Doctor of Social Work (DSW), University of Kentucky | Z3: Rachel Fitch, LCSW, helps individuals and families across Ohio find healing, hope, and renewed purpose through compassionate, evidencebased care. She works with adolescents, teens, and adults to navigate lifeâs most difficult challenges, including anxiety, depression, relationship struggles, and trauma. Rachel believes that therapy is a collaborative journeyâone that empowers clients to develop greater selfunderstanding, improve communication, and create lasting emotional balance. Rachel provides individual, couples, and family therapy at LifeStance Health, integrating Cognitive Behavioral Therapy CBT, mindfulness, and familybased approaches to support growth and resilience. She is experienced in helping clients facing complex concerns such as ADHD, postpartum depression, PTSDtrauma, and womenâs issues. Her approach combines clinical expertise with genuine warmth, allowing clients to feel supported and understood as they work toward their goals. Rachel is especially passionate about supporting individuals who have recently been discharged from a psychiatric hospital, helping them transition safely and confidently back into daily life. She offers structured guidance and emotional support to promote stability, reduce relapse risk, and strengthen coping skills. Rachel also works extensively with clinicians, first responders, and child welfare professionals experiencing burnout or secondary trauma, helping them rediscover balance and meaning in their personal and professional lives. Her practice welcomes diverse populations, including members of the LGBTQ community, military personnel and veterans, women, and individuals from adoption or foster care backgrounds. Rachelâs dedication to traumainformed and inclusive care ensures that every client feels seen and valued. Outside of her clinical work, Rachel enjoys reading, DIY home projects with her husband, and spending time with their two dogs. These personal passions reflect her belief in creating comfort, connection, and creativityâboth in her home and in her therapeutic work. | AZ3: English | BC3: pt_5pmdAWg-0UuZBxgghGIfih | BE3: Practitioner - Full Profile | BG3: No | BI3: =IFERROR(INDEX(ValidationAndReference!P:P, MATCH(BE3, ValidationAndReference!Q:Q, 0)), "") | BJ3: =IFERROR(INDEX(ValidationAndReference!F:F, MATCH(D3, ValidationAndReference!G:G, 0)), "") | BK3: =IFERROR(INDEX(ValidationAndReference!F:F, MATCH(E3, ValidationAndReference!G:G, 0)), "") | BL3: =IFERROR(INDEX(ValidationAndReference!F:F, MATCH(F3, ValidationAndReference!G:G, 0)), "") | BM3: 352 | BR3: lo_Co2PtuT10kC3DHSCyaUKPh | CL3: =IFERROR(INDEX(ValidationAndReference!V:V, MATCH(AZ3, ValidationAndReference!W:W, 0)), "") | CM3: =IFERROR(INDEX(ValidationAndReference!V:V, MATCH(BA3, ValidationAndReference!W:W, 0)), "") | CN3: =IFERROR(INDEX(ValidationAndReference!V:V, MATCH(BB3, ValidationAndReference!W:W, 0)), "") | CO3: 1077 State Rte 28 | CP3: Milford | CQ3: 45150 | CR3: OH | CS3: Ste 202 | CT3: No - Facility Zip
A4: Rachel | B4: Fitch | C4: Female | D4: DSW | E4: LISW-S | F4: LCSW | G4: =IFERROR(VLOOKUP(BM4, ValidationAndReference!J:K, 2, FALSE), "") | L4: Both | M4: LifeStance Health | N4: =IFERROR(INDEX(Location!X:X, MATCH(BR4, Location!W:W, 0)), "") | O4: =IFERROR(INDEX(Location!X:X, MATCH(BS4, Location!W:W, 0)), "") | S4: 1013105469 | T4: https://prod-clinicians-photo.s3.amazonaws.com/1013105469.jpg | U4: Doctor of Social Work (DSW), University of Kentucky | Z4: Rachel Fitch, LCSW, helps individuals and families across Ohio find healing, hope, and renewed purpose through compassionate, evidencebased care. She works with adolescents, teens, and adults to navigate lifeâs most difficult challenges, including anxiety, depression, relationship struggles, and trauma. Rachel believes that therapy is a collaborative journeyâone that empowers clients to develop greater selfunderstanding, improve communication, and create lasting emotional balance. Rachel provides individual, couples, and family therapy at LifeStance Health, integrating Cognitive Behavioral Therapy CBT, mindfulness, and familybased approaches to support growth and resilience. She is experienced in helping clients facing complex concerns such as ADHD, postpartum depression, PTSDtrauma, and womenâs issues. Her approach combines clinical expertise with genuine warmth, allowing clients to feel supported and understood as they work toward their goals. Rachel is especially passionate about supporting individuals who have recently been discharged from a psychiatric hospital, helping them transition safely and confidently back into daily life. She offers structured guidance and emotional support to promote stability, reduce relapse risk, and strengthen coping skills. Rachel also works extensively with clinicians, first responders, and child welfare professionals experiencing burnout or secondary trauma, helping them rediscover balance and meaning in their personal and professional lives. Her practice welcomes diverse populations, including members of the LGBTQ community, military personnel and veterans, women, and individuals from adoption or foster care backgrounds. Rachelâs dedication to traumainformed and inclusive care ensures that every client feels seen and valued. Outside of her clinical work, Rachel enjoys reading, DIY home projects with her husband, and spending time with their two dogs. These personal passions reflect her belief in creating comfort, connection, and creativityâboth in her home and in her therapeutic work. | AZ4: English | BC4: pt_5pmdAWg-0UuZBxgghGIfih | BE4: Practitioner - Full Profile | BG4: No | BI4: =IFERROR(INDEX(ValidationAndReference!P:P, MATCH(BE4, ValidationAndReference!Q:Q, 0)), "") | BJ4: =IFERROR(INDEX(ValidationAndReference!F:F, MATCH(D4, ValidationAndReference!G:G, 0)), "") | BK4: =IFERROR(INDEX(ValidationAndReference!F:F, MATCH(E4, ValidationAndReference!G:G, 0)), "") | BL4: =IFERROR(INDEX(ValidationAndReference!F:F, MATCH(F4, ValidationAndReference!G:G, 0)), "") | BM4: 352 | BR4: lo_Co2PtuT10kC3DHSCyaUKPh | CL4: =IFERROR(INDEX(ValidationAndReference!V:V, MATCH(AZ4, ValidationAndReference!W:W, 0)), "") | CM4: =IFERROR(INDEX(ValidationAndReference!V:V, MATCH(BA4, ValidationAndReference!W:W, 0)), "") | CN4: =IFERROR(INDEX(ValidationAndReference!V:V, MATCH(BB4, ValidationAndReference!W:W, 0)), "") | CO4: 1077 State Rte 28 | CP4: Milford | CQ4: 45150 | CR4: OH | CS4: Ste 202 | CT4: No - Facility Zip
A5: Ellie | B5: Ettman | C5: Female | D5: LPC | E5: CCTP | G5: =IFERROR(VLOOKUP(BM5, ValidationAndReference!J:K, 2, FALSE), "") | L5: Both | M5: LifeStance Health | N5: =IFERROR(INDEX(Location!X:X, MATCH(BR5, Location!W:W, 0)), "") | O5: =IFERROR(INDEX(Location!X:X, MATCH(BS5, Location!W:W, 0)), "") | S5: 1023668134 | T5: https://prod-clinicians-photo.s3.amazonaws.com/1023668134.jpg | U5: Master in Counseling (MC), Arcadia University | Z5: Ellie Ettman, LPC, helps teens, young adults, and adults in Pennsylvania navigate mental health challenges and improve overall wellbeing through compassionate, individualized care. As a Licensed Professional Counselor at LifeStance Health, she provides support for anxiety, depression, and relationship concerns, helping clients build practical strategies for managing symptoms and achieving personal growth. Ellie works with a diverse range of patients, including those recently discharged from psychiatric hospitals, ensuring each personâs unique circumstances are considered in their treatment plan. Ellie is particularly passionate about working with clients who have recently been discharged from psychiatric care or are navigating current legal matters. She helps individuals manage anxiety, depression, and relationship issues, using interventions such as Cognitive Behavioral Therapy CBT, Acceptance and Commitment Therapy ACT, couples counseling, and parenting skills. She serves populations including LGBTQ individuals, adults with developmental disabilities, and both men and women, creating a safe and inclusive environment for healing and personal development. Outside of her professional work, Ellie enjoys baking, spending time with family and friends, and finding ways to bring joy into everyday life. Her approach to therapy combines clinical expertise with genuine empathy, helping clients explore their goals, strengthen coping strategies, and improve their quality of life. | AZ5: English | BC5: pt_NQMRQWBlP02-a4WEulV9ph | BE5: Practitioner - Full Profile | BG5: No | BI5: =IFERROR(INDEX(ValidationAndReference!P:P, MATCH(BE5, ValidationAndReference!Q:Q, 0)), "") | BJ5: =IFERROR(INDEX(ValidationAndReference!F:F, MATCH(D5, ValidationAndReference!G:G, 0)), "") | BK5: =IFERROR(INDEX(ValidationAndReference!F:F, MATCH(E5, ValidationAndReference!G:G, 0)), "") | BL5: =IFERROR(INDEX(ValidationAndReference!F:F, MATCH(F5, ValidationAndReference!G:G, 0)), "") | BM5: 352 | BR5: lo_El9sSz8bXUelY14uudbaUB | CL5: =IFERROR(INDEX(ValidationAndReference!V:V, MATCH(AZ5, ValidationAndReference!W:W, 0)), "") | CM5: =IFERROR(INDEX(ValidationAndReference!V:V, MATCH(BA5, ValidationAndReference!W:W, 0)), "") | CN5: =IFERROR(INDEX(ValidationAndReference!V:V, MATCH(BB5, ValidationAndReference!W:W, 0)), "") | CO5: 140 W Ge | CP5: Plymouth Meeting | CQ5: 19462 | CR5: PA | CS5: Rmantown Pike Ste 160 | CT5: No - Facility Zip
A6: Ellie | B6: Ettman | C6: Female | D6: LPC | E6: CCTP | G6: =IFERROR(VLOOKUP(BM6, ValidationAndReference!J:K, 2, FALSE), "") | L6: Both | M6: LifeStance Health | N6: =IFERROR(INDEX(Location!X:X, MATCH(BR6, Location!W:W, 0)), "") | O6: =IFERROR(INDEX(Location!X:X, MATCH(BS6, Location!W:W, 0)), "") | S6: 1023668134 | T6: https://prod-clinicians-photo.s3.amazonaws.com/1023668134.jpg | U6: Master in Counseling (MC), Arcadia University | Z6: Ellie Ettman, LPC, helps teens, young adults, and adults in Pennsylvania navigate mental health challenges and improve overall wellbeing through compassionate, individualized care. As a Licensed Professional Counselor at LifeStance Health, she provides support for anxiety, depression, and relationship concerns, helping clients build practical strategies for managing symptoms and achieving personal growth. Ellie works with a diverse range of patients, including those recently discharged from psychiatric hospitals, ensuring each personâs unique circumstances are considered in their treatment plan. Ellie is particularly passionate about working with clients who have recently been discharged from psychiatric care or are navigating current legal matters. She helps individuals manage anxiety, depression, and relationship issues, using interventions such as Cognitive Behavioral Therapy CBT, Acceptance and Commitment Therapy ACT, couples counseling, and parenting skills. She serves populations including LGBTQ individuals, adults with developmental disabilities, and both men and women, creating a safe and inclusive environment for healing and personal development. Outside of her professional work, Ellie enjoys baking, spending time with family and friends, and finding ways to bring joy into everyday life. Her approach to therapy combines clinical expertise with genuine empathy, helping clients explore their goals, strengthen coping strategies, and improve their quality of life. | AZ6: English | BC6: pt_NQMRQWBlP02-a4WEulV9ph | BE6: Practitioner - Full Profile | BG6: No | BI6: =IFERROR(INDEX(ValidationAndReference!P:P, MATCH(BE6, ValidationAndReference!Q:Q, 0)), "") | BJ6: =IFERROR(INDEX(ValidationAndReference!F:F, MATCH(D6, ValidationAndReference!G:G, 0)), "") | BK6: =IFERROR(INDEX(ValidationAndReference!F:F, MATCH(E6, ValidationAndReference!G:G, 0)), "") | BL6: =IFERROR(INDEX(ValidationAndReference!F:F, MATCH(F6, ValidationAndReference!G:G, 0)), "") | BM6: 352 | BR6: lo_El9sSz8bXUelY14uudbaUB | CL6: =IFERROR(INDEX(ValidationAndReference!V:V, MATCH(AZ6, ValidationAndReference!W:W, 0)), "") | CM6: =IFERROR(INDEX(ValidationAndReference!V:V, MATCH(BA6, ValidationAndReference!W:W, 0)), "") | CN6: =IFERROR(INDEX(ValidationAndReference!V:V, MATCH(BB6, ValidationAndReference!W:W, 0)), "") | CO6: 140 W Ge | CP6: Plymouth Meeting | CQ6: 19462 | CR6: PA | CS6: Rmantown Pike Ste 160 | CT6: No - Facility Zip
A7: Mary | B7: Wyman | C7: Female | D7: MSW | E7: LCSW | G7: =IFERROR(VLOOKUP(BM7, ValidationAndReference!J:K, 2, FALSE), "") | L7: Both | M7: LifeStance Health | N7: =IFERROR(INDEX(Location!X:X, MATCH(BR7, Location!W:W, 0)), "") | O7: =IFERROR(INDEX(Location!X:X, MATCH(BS7, Location!W:W, 0)), "") | S7: 1043882244 | T7: https://prod-clinicians-photo.s3.amazonaws.com/1043882244.jpg | U7: Master of Social Work (MSW), California State University - Long Beach | Z7: Mary Lukens Wyman, LCSW, helps individuals in California navigate lifeâs challenges with warmth, compassion, and clinical expertise. She provides a safe and collaborative environment for adults and teens to explore their emotions, develop coping skills, and create meaningful change. Mary works with clients experiencing anxiety, depression, bipolar disorder, and life transitions, offering evidencebased strategies to help them regain balance, improve emotional wellbeing, and enhance daily functioning. Drawing on more than two decades of experience, Mary takes a holistic approach that integrates Cognitive Behavioral Therapy CBT, Dialectical Behavior Therapy DBT, and mindfulness techniques. She believes in helping clients build insight into their thoughts and behaviors while developing tools to foster resilience and selfacceptance. Her therapeutic style emphasizes understanding, practical skillbuilding, and empowering clients to take an active role in their healing process. Mary has a particular passion for supporting individuals through grief, midlife transitions, and postpartum challenges. She is dedicated to helping clients navigate the emotional complexity of these experiences, promoting healing, and guiding them toward renewed purpose and stability. Whether clients are facing loss, adjusting to a new phase of life, or managing the emotional demands of parenthood, Mary provides a compassionate, steady presence. In addition to her clinical work, Mary has specialized experience working with members of the LGBTQ community, individuals with developmental disabilities, and first responders. She values inclusivity and approaches therapy with sensitivity to each clientâs unique life experiences. Outside the therapy room, Mary enjoys ballet, sewing, baking, gardening, biking, and spending time with her dogâall of which nurture her own sense of balance and creativity. | AZ7: English | BC7: pt_06Ie2RxfpECXX_EgrAt4yB | BE7: Practitioner - Full Profile | BG7: No | BI7: =IFERROR(INDEX(ValidationAndReference!P:P, MATCH(BE7, ValidationAndReference!Q:Q, 0)), "") | BJ7: =IFERROR(INDEX(ValidationAndReference!F:F, MATCH(D7, ValidationAndReference!G:G, 0)), "") | BK7: =IFERROR(INDEX(ValidationAndReference!F:F, MATCH(E7, ValidationAndReference!G:G, 0)), "") | BL7: =IFERROR(INDEX(ValidationAndReference!F:F, MATCH(F7, ValidationAndReference!G:G, 0)), "") | BM7: 352 | BR7: lo_Ot2lyEXJIEiykEAMRqlk1R | BS7: lo_H01GEikbXUW62tziz7NntR | CL7: =IFERROR(INDEX(ValidationAndReference!V:V, MATCH(AZ7, ValidationAndReference!W:W, 0)), "") | CM7: =IFERROR(INDEX(ValidationAndReference!V:V, MATCH(BA7, ValidationAndReference!W:W, 0)), "") | CN7: =IFERROR(INDEX(ValidationAndReference!V:V, MATCH(BB7, ValidationAndReference!W:W, 0)), "") | CO7: 4361 Latham St | CP7: Riverside | CQ7: 92501 | CR7: CA | CT7: No - Facility Zip
A8: Argenis | B8: Mendoza | C8: Male | D8: PMHNP-BC | G8: =IFERROR(VLOOKUP(BM8, ValidationAndReference!J:K, 2, FALSE), "") | L8: Both | M8: LifeStance Health | N8: =IFERROR(INDEX(Location!X:X, MATCH(BR8, Location!W:W, 0)), "") | O8: =IFERROR(INDEX(Location!X:X, MATCH(BS8, Location!W:W, 0)), "") | S8: 1114639911 | T8: https://prod-clinicians-photo.s3.amazonaws.com/1114639911.jpg | U8: MSN, West Coast University | Z8: Argenis Alberto Mendoza helps adults across California find clarity, stability, and meaningful relief through thoughtful, collaborative psychiatric care. As a prescriber at LifeStance Health, he supports patients ages 18 through 64 who are seeking help with conditions such as Anxiety, Depression, and ADHD. Argenis approaches treatment with warmth, clinical precision, and a deep respect for each personâs lived experience, ensuring that individuals throughout California receive accessible, patientcentered mental health support. Argenis frequently works with patients managing complex and interrelated concerns, including Bipolar Disorder, Sleep Disorders, Psychosis or Schizophrenia, and Menâs Issues. His practice also includes supporting individuals facing PostPartum Depression and Anxiety, as well as the emotional challenges associated with grief and trauma. With experience treating a wide range of psychiatric conditionsâand with additional areas of expertiseâhe tailors care plans to reflect each patientâs goals, strengths, and cultural context. He is especially passionate about serving Military and Veteran communities, as well as First Responders and Spanishspeaking individuals throughout Southern California. Argenis understands the unique stressors, identity shifts, and resilience inherent within these groups. His approach combines evidencebased medication management with supportive interventions such as Acceptance and Commitment Therapy and Mindfulness strategies to promote emotional regulation, healthier routines, and longterm wellness. Argenis also welcomes men seeking care for challenges ranging from performance stress to emotional suppression, offering a safe space to explore mental health with respect and confidentiality. He provides additional treatment options to meet diverse needs and collaborates closely with each patient to monitor progress and refine care over time. Outside of his clinical work, Argenis enjoys spending time with his family, working out when he can, and playing video games. | AZ8: English | BA8: Spanish | BC8: pt_06Ie2RxfpECXX_EgrAt4yB | BE8: Practitioner - Full Profile | BG8: No | BI8: =IFERROR(INDEX(ValidationAndReference!P:P, MATCH(BE8, ValidationAndReference!Q:Q, 0)), "") | BJ8: =IFERROR(INDEX(ValidationAndReference!F:F, MATCH(D8, ValidationAndReference!G:G, 0)), "") | BK8: =IFERROR(INDEX(ValidationAndReference!F:F, MATCH(E8, ValidationAndReference!G:G, 0)), "") | BL8: =IFERROR(INDEX(ValidationAndReference!F:F, MATCH(F8, ValidationAndReference!G:G, 0)), "") | BM8: 405 | BR8: lo_iNarPd6X7EqUW7XZ-ciqwB | BS8: lo_Ie5kAh72ZUGfcxcTAKUmMx | CL8: =IFERROR(INDEX(ValidationAndReference!V:V, MATCH(AZ8, ValidationAndReference!W:W, 0)), "") | CM8: =IFERROR(INDEX(ValidationAndReference!V:V, MATCH(BA8, ValidationAndReference!W:W, 0)), "") | CN8: =IFERROR(INDEX(ValidationAndReference!V:V, MATCH(BB8, ValidationAndReference!W:W, 0)), "") | CO8: 2300 Boswell Rd | CP8: Chula Vista | CQ8: 91914 | CR8: CA | CT8: No - Facility Zip
A9: Demetrius | B9: Smith | C9: Male | G9: =IFERROR(VLOOKUP(BM9, ValidationAndReference!J:K, 2, FALSE), "") | L9: Adult | M9: LifeStance Health | N9: =IFERROR(INDEX(Location!X:X, MATCH(BR9, Location!W:W, 0)), "") | O9: =IFERROR(INDEX(Location!X:X, MATCH(BS9, Location!W:W, 0)), "") | S9: 1114643400 | T9: https://prod-clinicians-photo.s3.amazonaws.com/1114643400.jpg | U9: Master of Science Psychology (MSPSY), Capella University | Z9: Demetrius Smith helps adults in Georgia navigate anxiety, depression, and trauma with a grounded, compassionate approach designed to support meaningful and lasting change. He provides individual therapy through LifeStance Health and works with adults across a wide range of life stages, offering a steady, collaborative space where clients can explore challenges and build new strategies for emotional wellbeing. A core focus of Demetriusâs work is addressing the impact of race and povertyinduced trauma, an area he is deeply committed to because of the significant ways these stressors affect mental health, resilience, and daily functioning. He integrates this passion into treatment by helping clients unpack complex emotional experiences, strengthen identity, and develop practical tools for navigating environments shaped by adversity. Demetrius specializes in anxiety, depression, and PTSDtrauma and offers additional clinical support for concerns such as ADHD and life transitions. His work frequently involves adults connected to adoption and foster care settings, first responders, and military and veteran communities. He uses evidencebased interventionsâincluding Cognitive Behavioral Therapy, Dialectical Behavior Therapy, and Mindfulnessâand provides additional approaches as clinically appropriate. Demetriusâs dedication to underserved and innercity communities has shaped his longterm mission to expand access, resources, and support systems for individuals who face structural barriers to mental health care. Outside of his clinical work, he enjoys traveling, learning from different cultures, and spending meaningful time with close friends and loved ones. Demetrius serves patients throughout Georgia through LifeStance Health | AZ9: English | BC9: pt_2QxThMYj9E2Jwx1NRXHtxR | BE9: Practitioner - Full Profile | BG9: No | BI9: =IFERROR(INDEX(ValidationAndReference!P:P, MATCH(BE9, ValidationAndReference!Q:Q, 0)), "") | BJ9: =IFERROR(INDEX(ValidationAndReference!F:F, MATCH(D9, ValidationAndReference!G:G, 0)), "") | BK9: =IFERROR(INDEX(ValidationAndReference!F:F, MATCH(E9, ValidationAndReference!G:G, 0)), "") | BL9: =IFERROR(INDEX(ValidationAndReference!F:F, MATCH(F9, ValidationAndReference!G:G, 0)), "") | BM9: 352 | BR9: lo_6OQNV1lLBk2cUdmy1xYQ7B | BS9: lo_2cQf2-zB_k-kwoVM1OfbfB | CL9: =IFERROR(INDEX(ValidationAndReference!V:V, MATCH(AZ9, ValidationAndReference!W:W, 0)), "") | CM9: =IFERROR(INDEX(ValidationAndReference!V:V, MATCH(BA9, ValidationAndReference!W:W, 0)), "") | CN9: =IFERROR(INDEX(ValidationAndReference!V:V, MATCH(BB9, ValidationAndReference!W:W, 0)), "") | CO9: 2801 Buford Hwy | CP9: Brookhaven | CQ9: 30329 | CR9: GA | CS9: Ste 100 | CT9: No - Facility Zip
A10: Terry | B10: Foytek | C10: Female | D10: Professional | E10: Counselor | F10: LPC Associate | G10: =IFERROR(VLOOKUP(BM10, ValidationAndReference!J:K, 2, FALSE), "") | L10: Pediatric | M10: LifeStance Health | N10: =IFERROR(INDEX(Location!X:X, MATCH(BR10, Location!W:W, 0)), "") | O10: =IFERROR(INDEX(Location!X:X, MATCH(BS10, Location!W:W, 0)), "") | S10: 1124997390 | T10: https://prod-clinicians-photo.s3.amazonaws.com/1124997390.jpg | U10: Master of Science in Education in Guidance & Counseling- Elementary School, University of Wisconsin Superior | Z10: Terry Foytek helps children and teens across Oregon strengthen emotional resilience, understand their feelings, and develop healthier ways to cope with lifeâs challenges. She creates a warm, supportive environment where young clientsâranging from early childhood through adolescenceâcan safely explore their concerns and build skills that support longterm wellbeing. Families seeking child therapy in Oregon often turn to Terry for her calm presence, practical strategies, and ability to connect with children at every developmental stage. Terry is especially passionate about supporting young people with ADHD, anxiety, and depressionâconditions that often interfere with school success, relationships, and confidence. She also works extensively with childhood behavior issues and grief, helping children process difficult emotions and learn new ways of communicating and problemsolving. Her approach is collaborative and rooted in evidencebased care that empowers both children and their caregivers. Terry has a dedicated focus on helping children who experience school avoidance, offering structured strategies and supportive guidance to reduce anxiety, rebuild motivation, and strengthen coping skills. She understands how stressful school resistance can be for families and works closely with them to create achievable plans that promote a smoother and more positive school experience. She also provides care for children with Autism Spectrum Disorders and offers additional expertise for families seeking specialized mental health support. Terry integrates Cognitive Behavioral Therapy and mindfulnessbased interventions into her work, tailoring each session to meet the unique needs of her young clients. Outside of her practice, Terry enjoys spending time with family and friends, camping in Oregonâs natural spaces, swimming, and unwinding with a favorite show on Netflix or Hulu. | AZ10: English | BC10: pt_7gzlz71zrUWLpb31Rir9Rh | BE10: Practitioner - Full Profile | BG10: No | BI10: =IFERROR(INDEX(ValidationAndReference!P:P, MATCH(BE10, ValidationAndReference!Q:Q, 0)), "") | BJ10: =IFERROR(INDEX(ValidationAndReference!F:F, MATCH(D10, ValidationAndReference!G:G, 0)), "") | BK10: =IFERROR(INDEX(ValidationAndReference!F:F, MATCH(E10, ValidationAndReference!G:G, 0)), "") | BL10: =IFERROR(INDEX(ValidationAndReference!F:F, MATCH(F10, ValidationAndReference!G:G, 0)), "") | BR10: lo_MoqSTGcEEEuZQyKUwN9mZh | CL10: =IFERROR(INDEX(ValidationAndReference!V:V, MATCH(AZ10, ValidationAndReference!W:W, 0)), "") | CM10: =IFERROR(INDEX(ValidationAndReference!V:V, MATCH(BA10, ValidationAndReference!W:W, 0)), "") | CN10: =IFERROR(INDEX(ValidationAndReference!V:V, MATCH(BB10, ValidationAndReference!W:W, 0)), "") | CO10: 44 Clb Rd | CP10: Eugene | CQ10: 97401 | CR10: OR | CT10: No - Facility Zip
A11: Deepa | B11: Samaroo | C11: Female | D11: MSW | E11: LCSW | G11: =IFERROR(VLOOKUP(BM11, ValidationAndReference!J:K, 2, FALSE), "") | L11: Both | M11: LifeStance Health | N11: =IFERROR(INDEX(Location!X:X, MATCH(BR11, Location!W:W, 0)), "") | O11: =IFERROR(INDEX(Location!X:X, MATCH(BS11, Location!W:W, 0)), "") | S11: 1144678178 | T11: https://prod-clinicians-photo.s3.amazonaws.com/1144678178.jpg | U11: Master of Social Work (MSW), Barry University | Z11: Deepa Samaroo helps children, teens, and adults across Florida navigate emotional challenges and find lasting balance through compassionate, evidencebased therapy. She creates a safe, supportive space where clients can explore lifeâs difficulties, develop coping skills, and strengthen emotional resilience. Deepa provides individual therapy to address a wide range of concerns, including anxiety, depression, trauma, and behavioral issues, helping clients of all ages achieve meaningful change and improved wellbeing. Deepa specializes in working with anxiety, trauma, and moodrelated challenges such as depression and bipolar disorder. Using therapeutic methods like Cognitive Behavioral Therapy CBT, Eye Movement Desensitization and Reprocessing EMDR, and mindfulnessbased interventions, she tailors treatment to meet each personâs unique needs. Her compassionate yet structured approach helps clients uncover patterns that contribute to distress and replace them with healthier, more effective ways of thinking and living. Deepa also provides care for individuals and families navigating complex experiences such as developmental disabilities, adoption or foster care transitions, and stress related to first responder and military service. She understands how these experiences can affect identity, relationships, and mental health, and she works collaboratively to foster healing and strength. In addition, she integrates her training in play therapy and traumafocused care to support younger clients and families in building trust and emotional awareness. Deepaâs work is guided by empathy, insight, and a deep belief in each personâs ability to grow and thrive. She enjoys playing piano and basketball with her husbandâactivities that reflect her appreciation for balance, connection, and creativity both inside and outside the therapy room. Deepa Samaroo practices at LifeStance Health and serves patients throughout Florida. | AZ11: English | BC11: pt_9pBYQvTE2k-LMM9_puwu-h | BE11: Practitioner - Full Profile | BG11: No | BI11: =IFERROR(INDEX(ValidationAndReference!P:P, MATCH(BE11, ValidationAndReference!Q:Q, 0)), "") | BJ11: =IFERROR(INDEX(ValidationAndReference!F:F, MATCH(D11, ValidationAndReference!G:G, 0)), "") | BK11: =IFERROR(INDEX(ValidationAndReference!F:F, MATCH(E11, ValidationAndReference!G:G, 0)), "") | BL11: =IFERROR(INDEX(ValidationAndReference!F:F, MATCH(F11, ValidationAndReference!G:G, 0)), "") | BM11: 352 | BR11: lo_db_IKeI9b0SAE8r0M2VOAx | BS11: lo_U1vZvhOvSUuEPnSfqZ2FvB | CL11: =IFERROR(INDEX(ValidationAndReference!V:V, MATCH(AZ11, ValidationAndReference!W:W, 0)), "") | CM11: =IFERROR(INDEX(ValidationAndReference!V:V, MATCH(BA11, ValidationAndReference!W:W, 0)), "") | CN11: =IFERROR(INDEX(ValidationAndReference!V:V, MATCH(BB11, ValidationAndReference!W:W, 0)), "") | CO11: 10125 West Colonial Dr | CP11: Ocoee | CQ11: 34761 | CR11: FL | CT11: No - Facility Zip
A12: Rebecca | B12: Moore | C12: Female | D12: MD | G12: =IFERROR(VLOOKUP(BM12, ValidationAndReference!J:K, 2, FALSE), "") | L12: Both | M12: LifeStance Health | N12: =IFERROR(INDEX(Location!X:X, MATCH(BR12, Location!W:W, 0)), "") | O12: =IFERROR(INDEX(Location!X:X, MATCH(BS12, Location!W:W, 0)), "") | S12: 1154549269 | T12: https://prod-clinicians-photo.s3.amazonaws.com/1154549269.jpg | U12: M.D., Pennsylvania State University | Z12: Dr. Rebecca Moore helps patients across Colorado find clarity, emotional steadiness, and improved daily functioning through thoughtful psychiatric care grounded in evidencebased treatment. At LifeStance Health, she supports adults and seniors with a warm, collaborative approach to medication management that prioritizes safety, symptom relief, and longterm wellbeing. She is especially passionate about treating trauma and PTSD, somatoform disorders, with expertise in Functional Neurological Disorders, and psychiatric conditions occurring in individuals with autism and other developmental disabilities. Dr. Moore is known for her ability to translate complex mindâbody interactions into practical steps that empower patients, and she approaches trauma work with a focus on restoring both internal stability and confidence in navigating daily life. Her clinical work centers on anxiety, depression, and PTSDtrauma, while also offering care for additional mental health concerns that benefit from targeted medication management. She integrates psychiatric expertise with therapeutic principles such as Cognitive Behavioral Therapy, Mindfulness, and Acceptance and Commitment Therapy. She frequently supports populations including individuals with autism spectrum or developmental disabilities, first responders, and military or veteran communities, and she provides additional services tailored to their unique needs. Outside of her clinical role, Dr. Moore enjoys hiking Coloradoâs trails, running, participating in dog sports, and relaxing with knitting projects that keep her grounded and creative. Dedicated to improving mental health across Colorado, Dr. Moore welcomes patients seeking compassionate, clinically informed medication management. | AZ12: English | BC12: pt_Xdjx281Ba06vQlN0Fjw0Tx | BE12: Practitioner - Full Profile | BG12: No | BI12: =IFERROR(INDEX(ValidationAndReference!P:P, MATCH(BE12, ValidationAndReference!Q:Q, 0)), "") | BJ12: =IFERROR(INDEX(ValidationAndReference!F:F, MATCH(D12, ValidationAndReference!G:G, 0)), "") | BK12: =IFERROR(INDEX(ValidationAndReference!F:F, MATCH(E12, ValidationAndReference!G:G, 0)), "") | BL12: =IFERROR(INDEX(ValidationAndReference!F:F, MATCH(F12, ValidationAndReference!G:G, 0)), "") | BM12: 122 | BR12: lo_FKnY_xlGOUmMpsZqHn3oqB | BS12: lo_y5BCumyPdEuPNBypHIR_8h | CL12: =IFERROR(INDEX(ValidationAndReference!V:V, MATCH(AZ12, ValidationAndReference!W:W, 0)), "") | CM12: =IFERROR(INDEX(ValidationAndReference!V:V, MATCH(BA12, ValidationAndReference!W:W, 0)), "") | CN12: =IFERROR(INDEX(ValidationAndReference!V:V, MATCH(BB12, ValidationAndReference!W:W, 0)), "") | CO12: 7780 S Broadway | CP12: Littleton | CQ12: 80122 | CR12: CO | CT12: No - Facility Zip
A13: Nisha | B13: Jambulingam | C13: Female | D13: DO | G13: =IFERROR(VLOOKUP(BM13, ValidationAndReference!J:K, 2, FALSE), "") | L13: Both | M13: LifeStance Health | N13: =IFERROR(INDEX(Location!X:X, MATCH(BR13, Location!W:W, 0)), "") | O13: =IFERROR(INDEX(Location!X:X, MATCH(BS13, Location!W:W, 0)), "") | S13: 1164097721 | T13: https://prod-clinicians-photo.s3.amazonaws.com/1164097721.jpg | U13: DO, Michigan State University | Z13: Dr. Nisha Jambulingam, DO, provides compassionate, evidencebased psychiatric care to adults across Michigan. She offers medication management for young adults through midlife and beyond, helping individuals better understand and manage conditions that affect daily life, work, and relationships. Her goal is to create a safe, collaborative space where patients feel heard and supported as they work toward greater stability and overall wellbeing. Dr. Jambulingam specializes in treating anxiety and depression, with additional expertise in supporting individuals who have experienced trauma and PTSD. She partners closely with patients to develop treatment plans that address both immediate symptoms and longterm goals. Her approach balances clinical precision with empathy, ensuring that each patientâs care is personalized and effective. Mindfulness is an integral part of her practice, and she often incorporates it into her work to help patients reduce stress, improve focus, and build resilience. Whether someone is navigating persistent anxiety, overcoming the impact of trauma, or seeking greater clarity in daily life, Dr. Jambulingam provides both medical expertise and practical tools for living with calm and confidence. Outside of her work, Dr. Jambulingam enjoys playing tennis and traveling, pursuits that reflect her value of both discipline and exploration. These interests mirror the balance she encourages her patients to cultivate in their own lives. | AZ13: English | BC13: pt_2fAaDQkuJkeZYNO0YaxkCh | BE13: Practitioner - Full Profile | BG13: No | BI13: =IFERROR(INDEX(ValidationAndReference!P:P, MATCH(BE13, ValidationAndReference!Q:Q, 0)), "") | BJ13: =IFERROR(INDEX(ValidationAndReference!F:F, MATCH(D13, ValidationAndReference!G:G, 0)), "") | BK13: =IFERROR(INDEX(ValidationAndReference!F:F, MATCH(E13, ValidationAndReference!G:G, 0)), "") | BL13: =IFERROR(INDEX(ValidationAndReference!F:F, MATCH(F13, ValidationAndReference!G:G, 0)), "") | BR13: lo_BRTn0txJR0mRQSB-7QLaGh | BS13: lo_Sjb2xJj8o0ummoGM57inNB | CL13: =IFERROR(INDEX(ValidationAndReference!V:V, MATCH(AZ13, ValidationAndReference!W:W, 0)), "") | CM13: =IFERROR(INDEX(ValidationAndReference!V:V, MATCH(BA13, ValidationAndReference!W:W, 0)), "") | CN13: =IFERROR(INDEX(ValidationAndReference!V:V, MATCH(BB13, ValidationAndReference!W:W, 0)), "") | CO13: 1760 S Telegraph Rd | CP13: Bloomfield Hills | CQ13: 48302 | CR13: MI | CT13: No - Facility Zip
A14: Frances | B14: Crespo Bonilla | C14: Female | D14: PsyD | G14: =IFERROR(VLOOKUP(BM14, ValidationAndReference!J:K, 2, FALSE), "") | L14: Both | M14: LifeStance Health | N14: =IFERROR(INDEX(Location!X:X, MATCH(BR14, Location!W:W, 0)), "") | O14: =IFERROR(INDEX(Location!X:X, MATCH(BS14, Location!W:W, 0)), "") | S14: 1174870620 | T14: https://prod-clinicians-photo.s3.amazonaws.com/1174870620.jpg | U14: PsyD, Ponce School of Medicine | Z14: Frances Crespo helps children, adolescents, and young adults across Florida understand their cognitive, developmental, and emotional strengths through comprehensive psychological and neuropsychological testing at LifeStance Health. She provides evaluations for young children through individuals in their midtwenties, offering families clarity, diagnostic accuracy, and actionable recommendations that support longterm growth. With a clinical focus on ADHD and childhood behavior issues, Frances specializes in assessments that guide treatment planning, school accommodations, and individualized support strategies. She frequently works with children on the autism spectrum, individuals with developmental disabilities, and LGBTQ youth, tailoring each evaluation to the personâs developmental stage, learning profile, and lived experiences. Her testing process is structured, compassionate, and grounded in evidencebased practice. Although no additional specialties are designated for emphasis, Frances is deeply committed to helping families make sense of complex behavioral and developmental concerns. She understands how overwhelming unanswered questions can feel, especially for caregivers seeking the right resources for a child. Through clear feedback, accessible reports, and thoughtful guidance, she empowers families to move forward with confidence and direction. Frances offers neuropsychological testing and additional assessment services designed to evaluate attention, learning, executive functioning, emotional functioning, and developmental needs. Her goal is to ensure that each client receives an evaluation that is both clinically rigorous and practically useful across school, home, and community settings. Outside of her clinical work, Frances enjoys reading, hiking, biking, running, exploring new cities, appreciating art, spending time in nature, listening to music, and being with her dogs. These interests help her maintain balance and enrich the warm, grounded approach she brings to patients and families throughout Florida. | AZ14: Spanish | BA14: English | BC14: pt_9pBYQvTE2k-LMM9_puwu-h | BE14: Practitioner - Full Profile | BG14: No | BI14: =IFERROR(INDEX(ValidationAndReference!P:P, MATCH(BE14, ValidationAndReference!Q:Q, 0)), "") | BJ14: =IFERROR(INDEX(ValidationAndReference!F:F, MATCH(D14, ValidationAndReference!G:G, 0)), "") | BK14: =IFERROR(INDEX(ValidationAndReference!F:F, MATCH(E14, ValidationAndReference!G:G, 0)), "") | BL14: =IFERROR(INDEX(ValidationAndReference!F:F, MATCH(F14, ValidationAndReference!G:G, 0)), "") | BM14: 337 | BR14: lo_b09w2r967E6ivRuRmRKZBx | BS14: lo_DvgivwgDbUqPLVF2z7n_qR | CL14: =IFERROR(INDEX(ValidationAndReference!V:V, MATCH(AZ14, ValidationAndReference!W:W, 0)), "") | CM14: =IFERROR(INDEX(ValidationAndReference!V:V, MATCH(BA14, ValidationAndReference!W:W, 0)), "") | CN14: =IFERROR(INDEX(ValidationAndReference!V:V, MATCH(BB14, ValidationAndReference!W:W, 0)), "") | CO14: 260 Lookout Place | CP14: Maitland | CQ14: 32751 | CR14: FL | CT14: No - Facility Zip
A15: Kristen | B15: Cook | C15: Female | D15: LPC | G15: =IFERROR(VLOOKUP(BM15, ValidationAndReference!J:K, 2, FALSE), "") | L15: Both | M15: LifeStance Health | N15: =IFERROR(INDEX(Location!X:X, MATCH(BR15, Location!W:W, 0)), "") | O15: =IFERROR(INDEX(Location!X:X, MATCH(BS15, Location!W:W, 0)), "") | S15: 1235017286 | T15: https://prod-clinicians-photo.s3.amazonaws.com/1235017286.jpg | U15: Masters of Arts (MA), Texas A&M University - San Antonio | Z15: Mrs. Kristen Cook helps children, teens, adults, and seniors across Texas navigate lifeâs challenges with greater resilience and emotional balance. Practicing at LifeStance Health, she provides individual therapy in a supportive, engaging environment that encourages growth and healing. Kristen understands that every stage of life brings its own unique struggles, and she works collaboratively with each client to build practical coping skills, strengthen relationships, and foster lasting emotional wellbeing. Kristenâs approach integrates warmth, humor, and honesty to create a safe space where clients can express themselves freely and work toward meaningful change. Drawing from her background as an educator and counselor, she offers specialized care for anxiety, depression, and trauma, helping clients uncover the underlying causes of distress while developing tools to manage symptoms effectively. Her use of Eye Movement Desensitization and Reprocessing EMDR therapy supports healing from traumatic experiences and empowers clients to move forward with confidence and clarity. Kristen is especially passionate about working with individuals managing ADHD, PTSD, and moodrelated challenges such as depression and bipolar disorder. She believes in helping clients rediscover their strengths and find stability, whether they are coping with childhood behavioral issues, academic stress, or major life transitions. Kristen also provides affirming care for individuals with developmental differences and members of the LGBTQ community, ensuring that every person feels valued and understood throughout the therapeutic process. Outside of her clinical work, Kristen enjoys reading and creating crafts activities that inspire creativity, mindfulness, and a sense of calm that she often encourages her clients to cultivate in their own lives. | AZ15: English | BC15: pt_vOTgX4FPvUOFJaL-VrSO1B | BE15: Practitioner - Full Profile | BG15: No | BI15: =IFERROR(INDEX(ValidationAndReference!P:P, MATCH(BE15, ValidationAndReference!Q:Q, 0)), "") | BJ15: =IFERROR(INDEX(ValidationAndReference!F:F, MATCH(D15, ValidationAndReference!G:G, 0)), "") | BK15: =IFERROR(INDEX(ValidationAndReference!F:F, MATCH(E15, ValidationAndReference!G:G, 0)), "") | BL15: =IFERROR(INDEX(ValidationAndReference!F:F, MATCH(F15, ValidationAndReference!G:G, 0)), "") | BM15: 352 | BR15: lo_2they0iD2kme2mzq2VEnRR | BS15: lo_RBNdmowsJ0iESMl8yHZwHB | CL15: =IFERROR(INDEX(ValidationAndReference!V:V, MATCH(AZ15, ValidationAndReference!W:W, 0)), "") | CM15: =IFERROR(INDEX(ValidationAndReference!V:V, MATCH(BA15, ValidationAndReference!W:W, 0)), "") | CN15: =IFERROR(INDEX(ValidationAndReference!V:V, MATCH(BB15, ValidationAndReference!W:W, 0)), "") | CO15: 540 Oak Ctr Dr | CP15: San Antonio | CQ15: 78258 | CR15: TX | CT15: No - Facility Address (try converting 'Ctr' to 'CTR'; try converting 'Ctr' to 'CEN'; try converting 'Ctr' to 'CENT'; try converting 'Ctr' to 'CENTER'; try converting 'Ctr' to 'CENTR'; try converting 'Ctr' to 'CENTRE'; try converting 'Ctr' to 'CNTER'; try converting 'Ctr' to 'CNTR'; try converting 'Ctr' to 'CTR'; try converting 'Dr' to 'DR'; try converting 'Dr' to 'DR'; try converting 'Dr' to 'DRIV'; try converting 'Dr' to 'DRIVE'; try converting 'Dr' to 'DRV'), Facility Zip
A16: Stephanie | B16: Rivera | C16: Female | D16: LCSW | G16: =IFERROR(VLOOKUP(BM16, ValidationAndReference!J:K, 2, FALSE), "") | L16: Both | M16: LifeStance Health | N16: =IFERROR(INDEX(Location!X:X, MATCH(BR16, Location!W:W, 0)), "") | O16: =IFERROR(INDEX(Location!X:X, MATCH(BS16, Location!W:W, 0)), "") | S16: 1255091823 | T16: https://prod-clinicians-photo.s3.amazonaws.com/1255091823.jpg | U16: Master of Social Work (MSW), Boston University | Z16: Stephanie Rivera, LCSW, helps individuals in North Carolina navigate lifeâs challenges with compassion, collaboration, and evidencebased care. She works with children, teens, and adults to address a variety of emotional and behavioral concerns, helping her clients develop the tools they need to manage stress, improve relationships, and build resilience. Stephanie believes therapy should feel like a safe and supportive partnership where growth happens through understanding and empowerment. Stephanie specializes in treating anxiety and depression, drawing on her clinical experience to help clients better understand their thoughts, emotions, and behaviors. Using approaches such as Cognitive Behavioral Therapy CBT and Mindfulness, she supports individuals in identifying unhelpful patterns and creating meaningful change. Her therapeutic style is warm, goaloriented, and adapted to each personâs unique needs and strengths. A particular passion for Stephanie is working with members of the LGBTQ community, especially youth and young adults exploring identity and belonging. She creates an affirming environment where clients can process experiences of stress, anxiety, or selfdoubt while learning to embrace authenticity and selfacceptance. Stephanieâs work in this area reflects her deep commitment to fostering inclusion, empowerment, and emotional wellbeing across diverse backgrounds. Outside of her clinical work, Stephanie enjoys exploring new coffee shops, staying active through exercise, cooking creative meals, and relaxing with video games. | AZ16: English | BA16: Spanish | BC16: pt_JC64JlmALEqey1kShhAOLh | BE16: Practitioner - Full Profile | BG16: No | BI16: =IFERROR(INDEX(ValidationAndReference!P:P, MATCH(BE16, ValidationAndReference!Q:Q, 0)), "") | BJ16: =IFERROR(INDEX(ValidationAndReference!F:F, MATCH(D16, ValidationAndReference!G:G, 0)), "") | BK16: =IFERROR(INDEX(ValidationAndReference!F:F, MATCH(E16, ValidationAndReference!G:G, 0)), "") | BL16: =IFERROR(INDEX(ValidationAndReference!F:F, MATCH(F16, ValidationAndReference!G:G, 0)), "") | BM16: 352 | BR16: lo_CASH_KCrKUGIOjgNUDFxbB | BS16: lo_LozPsG8CpEq6Gr3e5WS5Ph | CL16: =IFERROR(INDEX(ValidationAndReference!V:V, MATCH(AZ16, ValidationAndReference!W:W, 0)), "") | CM16: =IFERROR(INDEX(ValidationAndReference!V:V, MATCH(BA16, ValidationAndReference!W:W, 0)), "") | CN16: =IFERROR(INDEX(ValidationAndReference!V:V, MATCH(BB16, ValidationAndReference!W:W, 0)), "") | CO16: 10620 Park Rd | CP16: Charlotte | CQ16: 28210 | CR16: NC | CT16: No - Facility Zip
A17: Jessica | B17: Kastin | C17: Female | D17: PsyD | G17: =IFERROR(VLOOKUP(BM17, ValidationAndReference!J:K, 2, FALSE), "") | L17: Both | M17: LifeStance Health | N17: =IFERROR(INDEX(Location!X:X, MATCH(BR17, Location!W:W, 0)), "") | O17: =IFERROR(INDEX(Location!X:X, MATCH(BS17, Location!W:W, 0)), "") | S17: 1316839657 | T17: https://prod-clinicians-photo.s3.amazonaws.com/1316839657.jpg | U17: PsyD, Pace University at New York City | Z17: Jessica Kastin provides compassionate, expert psychological testing and support for children, adolescents, and young adults across New York. At LifeStance Health, she is committed to helping clients and their families better understand emotional, behavioral, and developmental concerns through comprehensive evaluations. Jessica creates a safe, affirming space where individuals feel seen and supported, using her deep clinical insight to guide each assessment and treatment recommendation. With a strong focus on early childhood and adolescent development, Jessica specializes in psychological testing for ADHD, anxiety, and childhood behavior issues. She is particularly passionate about helping children and teens navigate the unique challenges related to trauma, school avoidance, and emotional regulation. Her assessments help families gain clarity, access resources, and advocate for the educational and therapeutic support their children need to thrive. Jessica has extensive experience working with youth in foster care and adoption, children on the autism spectrum, and individuals with developmental disabilities. She is especially attuned to the needs of LGBTQ youth and integrates a strengthsbased, identityaffirming approach into her work. Her evaluations are not just diagnostic toolsâthey are empowering experiences that give voice to a clientâs strengths and struggles while informing meaningful paths forward. Outside of her clinical work, Jessica enjoys cooking, baking, reading, and spending time with family and friends. Her warm, approachable style helps build trust with children and caregivers alike, making the evaluation process feel collaborative and supportive. | AZ17: English | BC17: pt_fvIkMYo3p0S6q91GK083xh | BE17: Practitioner - Full Profile | BG17: No | BI17: =IFERROR(INDEX(ValidationAndReference!P:P, MATCH(BE17, ValidationAndReference!Q:Q, 0)), "") | BJ17: =IFERROR(INDEX(ValidationAndReference!F:F, MATCH(D17, ValidationAndReference!G:G, 0)), "") | BK17: =IFERROR(INDEX(ValidationAndReference!F:F, MATCH(E17, ValidationAndReference!G:G, 0)), "") | BL17: =IFERROR(INDEX(ValidationAndReference!F:F, MATCH(F17, ValidationAndReference!G:G, 0)), "") | BM17: 337 | BR17: lo_ckiP2HKaREq2OT5YyitjcQ | BS17: lo_-JYceYOvcUCW42M5kdtHnA | CL17: =IFERROR(INDEX(ValidationAndReference!V:V, MATCH(AZ17, ValidationAndReference!W:W, 0)), "") | CM17: =IFERROR(INDEX(ValidationAndReference!V:V, MATCH(BA17, ValidationAndReference!W:W, 0)), "") | CN17: =IFERROR(INDEX(ValidationAndReference!V:V, MATCH(BB17, ValidationAndReference!W:W, 0)), "") | CO17: 10 Pearl St | CP17: Port Chester | CQ17: 10573 | CR17: NY | CT17: No - Facility Zip
A18: Sherri | B18: Creel | C18: Female | D18: LMHC | E18: MS | G18: =IFERROR(VLOOKUP(BM18, ValidationAndReference!J:K, 2, FALSE), "") | L18: Both | M18: LifeStance Health | N18: =IFERROR(INDEX(Location!X:X, MATCH(BR18, Location!W:W, 0)), "") | O18: =IFERROR(INDEX(Location!X:X, MATCH(BS18, Location!W:W, 0)), "") | S18: 1326168774 | T18: https://prod-clinicians-photo.s3.amazonaws.com/1326168774.jpg | U18: Master of Science in Counseling Psychology, Nova University | Z18: Sherri Lynn Creel helps individuals across Florida navigate emotional challenges with clarity, resilience, and practical therapeutic support. She provides care for children, adolescents, teens, adults, and seniors, offering a steady and compassionate presence for those seeking meaningful progress in their mental health. At LifeStance Health, she works with patients to address the concerns that most impact their daily lives, fostering growth, stability, and wellbeing throughout Florida. Sherri specializes in treating anxiety, depression, and ADHD, using evidencebased methods that help patients better understand their symptoms and build effective coping strategies. She also supports individuals experiencing childhood behavior issues and womenâs mental health concerns, offering additional expertise across a breadth of emotional and behavioral conditions. Her approach emphasizes collaboration, skill building, and helping each patient connect with their strengths. She is particularly passionate about supporting adoption and foster care populations, recognizing the unique emotional, relational, and developmental experiences that shape their mental health needs. Sherri works to create a safe and grounded therapeutic space where children, teens, and adults in these communities can process experiences, strengthen identity, and develop tools for longterm resilience. Sherri offers treatment rooted in Cognitive Behavioral Therapy, Dialectical Behavior Therapy, and mindfulnessbased approaches, with additional interventions available when needed. She tailors therapy to each patientâs goals, integrating parentingfocused strategies when working with families and younger clients. Outside the therapy room, Sherri is an avid runner and enjoys playing pickleball with her husband. She also loves visiting her sons in New York City and Tennessee, spending quality time with family whenever she can. Serving patients throughout Florida, Sherri Lynn Creel welcomes individuals and families seeking thoughtful, experienced mental health care. | AZ18: English | BC18: pt_9pBYQvTE2k-LMM9_puwu-h | BE18: Practitioner - Full Profile | BG18: No | BI18: =IFERROR(INDEX(ValidationAndReference!P:P, MATCH(BE18, ValidationAndReference!Q:Q, 0)), "") | BJ18: =IFERROR(INDEX(ValidationAndReference!F:F, MATCH(D18, ValidationAndReference!G:G, 0)), "") | BK18: =IFERROR(INDEX(ValidationAndReference!F:F, MATCH(E18, ValidationAndReference!G:G, 0)), "") | BL18: =IFERROR(INDEX(ValidationAndReference!F:F, MATCH(F18, ValidationAndReference!G:G, 0)), "") | BM18: 352 | BR18: lo_TNqCKeFZ70ylvjPe3aqLhh | BS18: lo_W97PaBwV8kyxcJadT4VXth | CL18: =IFERROR(INDEX(ValidationAndReference!V:V, MATCH(AZ18, ValidationAndReference!W:W, 0)), "") | CM18: =IFERROR(INDEX(ValidationAndReference!V:V, MATCH(BA18, ValidationAndReference!W:W, 0)), "") | CN18: =IFERROR(INDEX(ValidationAndReference!V:V, MATCH(BB18, ValidationAndReference!W:W, 0)), "") | CO18: 8400 Red Bug Lk Rd | CP18: Oviedo | CQ18: 32765 | CR18: FL | CT18: No - Facility Zip
